Workbook

Sheet EWG-CCP-125 (1)
A1: Ref. | B1: Glass ID | C1: Composition (mol%) | AC1: N4 | AE1: sum | AF1: Glass sample preperation details
C2: Al2O3 | D2: B2O3 | E2: CaO | F2: Cr2O3 | G2: Fe2O3 | H2: K2O | I2: Li2O | J2: MgO | K2: Na2O | L2: P2O5 | M2: SiO2 | N2: SO3 | O2: TiO2 | P2: ZnO | Q2: ZrO2 | R2: BaO | S2: Bi2O3 | T2: Cs2O | U2: HfO2 | V2: La2O3 | W2: PbO | X2: SrO | Y2: TeO2 | Z2: Rb2O | AA2: UO3 | AB2: Y2O3 | AC2: % | AD2: Method | AF2: Cooling rate | AG2: Annealing | AH2: Sample form | AI2: Pressure | AJ2: Note
A3: Yu, Yang, Baltzar Stevensson, and Mattias Edén. "Medium-range structural organization of phosphorus-bearing borosilicate glasses revealed by advanced solid-state NMR experiments and MD simulations: consequences of B/Si substitutions." The Journal of Physical Chemistry B 121.41 (2017): 9737-9752. | B3: S462.6(5) | C3: 0 | D3: 4.6 | E3: 26.7 | F3: 0 | G3: 0 | H3: 0 | I3: 0 | J3: 0 | K3: 24.6 | L3: 2.6 | M3: 41.5 | N3: 0 | O3: 0 | P3: 0 | Q3: 0 | R3: 0 | S3: 0 | T3: 0 | U3: 0 | V3: 0 | W3: 0 | X3: 0 | Y3: 0 | Z3: 0 | AA3: 0 | AB3: 0 | AC3: 16.9 | AD3: NMR | AE3: =SUM(C3:AB3) -> 100 | AF3: Water quench | AH3: Powder | AI3: Atm.
B4: S462.6(9) | C4: 0 | D4: 9.2 | E4: 26.7 | F4: 0 | G4: 0 | H4: 0 | I4: 0 | J4: 0 | K4: 24.6 | L4: 2.6 | M4: 36.9 | N4: 0 | O4: 0 | P4: 0 | Q4: 0 | R4: 0 | S4: 0 | T4: 0 | U4: 0 | V4: 0 | W4: 0 | X4: 0 | Y4: 0 | Z4: 0 | AA4: 0 | AB4: 0 | AC4: 26 | AD4: NMR | AE4: =SUM(C4:AB4) -> 100
B5: S462.6(14) | C5: 0 | D5: 13.8 | E5: 26.7 | F5: 0 | G5: 0 | H5: 0 | I5: 0 | J5: 0 | K5: 24.6 | L5: 2.6 | M5: 32.2 | N5: 0 | O5: 0 | P5: 0 | Q5: 0 | R5: 0 | S5: 0 | T5: 0 | U5: 0 | V5: 0 | W5: 0 | X5: 0 | Y5: 0 | Z5: 0 | AA5: 0 | AB5: 0 | AC5: 29.5 | AD5: NMR | AE5: =SUM(C5:AB5) -> 99.9
B6: S462.6(18) | C6: 0 | D6: 18.4 | E6: 26.7 | F6: 0 | G6: 0 | H6: 0 | I6: 0 | J6: 0 | K6: 24.6 | L6: 2.6 | M6: 27.7 | N6: 0 | O6: 0 | P6: 0 | Q6: 0 | R6: 0 | S6: 0 | T6: 0 | U6: 0 | V6: 0 | W6: 0 | X6: 0 | Y6: 0 | Z6: 0 | AA6: 0 | AB6: 0 | AC6: 31.6 | AD6: NMR | AE6: =SUM(C6:AB6) -> 100
B7: S462.6(28) | C7: 0 | D7: 27.7 | E7: 26.7 | F7: 0 | G7: 0 | H7: 0 | I7: 0 | J7: 0 | K7: 24.6 | L7: 2.6 | M7: 18.4 | N7: 0 | O7: 0 | P7: 0 | Q7: 0 | R7: 0 | S7: 0 | T7: 0 | U7: 0 | V7: 0 | W7: 0 | X7: 0 | Y7: 0 | Z7: 0 | AA7: 0 | AB7: 0 | AC7: 33.5 | AD7: NMR | AE7: =SUM(C7:AB7) -> 100
B8: S462.6(37) | C8: 0 | D8: 36.9 | E8: 26.7 | F8: 0 | G8: 0 | H8: 0 | I8: 0 | J8: 0 | K8: 24.6 | L8: 2.6 | M8: 9.2 | N8: 0 | O8: 0 | P8: 0 | Q8: 0 | R8: 0 | S8: 0 | T8: 0 | U8: 0 | V8: 0 | W8: 0 | X8: 0 | Y8: 0 | Z8: 0 | AA8: 0 | AB8: 0 | AC8: 34 | AD8: NMR | AE8: =SUM(C8:AB8) -> 100
B9: S462.6(46) | C9: 0 | D9: 46.1 | E9: 26.7 | F9: 0 | G9: 0 | H9: 0 | I9: 0 | J9: 0 | K9: 24.6 | L9: 2.6 | M9: 0 | N9: 0 | O9: 0 | P9: 0 | Q9: 0 | R9: 0 | S9: 0 | T9: 0 | U9: 0 | V9: 0 | W9: 0 | X9: 0 | Y9: 0 | Z9: 0 | AA9: 0 | AB9: 0 | AC9: 33.4 | AD9: NMR | AE9: =SUM(C9:AB9) -> 100
B10: S464.0(2) | C10: 0 | D10: 2.4 | E10: 23.3 | F10: 0 | G10: 0 | H10: 0 | I10: 0 | J10: 0 | K10: 24.1 | L10: 4 | M10: 46.2 | N10: 0 | O10: 0 | P10: 0 | Q10: 0 | R10: 0 | S10: 0 | T10: 0 | U10: 0 | V10: 0 | W10: 0 | X10: 0 | Y10: 0 | Z10: 0 | AA10: 0 | AB10: 0 | AC10: 36.5 | AD10: NMR | AE10: =SUM(C10:AB10) -> 100
B11: S464.0(5) | C11: 0 | D11: 4.9 | E11: 23.3 | F11: 0 | G11: 0 | H11: 0 | I11: 0 | J11: 0 | K11: 24.1 | L11: 4 | M11: 43.7 | N11: 0 | O11: 0 | P11: 0 | Q11: 0 | R11: 0 | S11: 0 | T11: 0 | U11: 0 | V11: 0 | W11: 0 | X11: 0 | Y11: 0 | Z11: 0 | AA11: 0 | AB11: 0 | AC11: 38.8 | AD11: NMR | AE11: =SUM(C11:AB11) -> 100
B12: S464.0(7) | C12: 0 | D12: 7.3 | E12: 23.3 | F12: 0 | G12: 0 | H12: 0 | I12: 0 | J12: 0 | K12: 24.1 | L12: 4 | M12: 41.3 | N12: 0 | O12: 0 | P12: 0 | Q12: 0 | R12: 0 | S12: 0 | T12: 0 | U12: 0 | V12: 0 | W12: 0 | X12: 0 | Y12: 0 | Z12: 0 | AA12: 0 | AB12: 0 | AC12: 41.1 | AD12: NMR | AE12: =SUM(C12:AB12) -> 100
B13: S464.0(10) | C13: 0 | D13: 9.7 | E13: 23.3 | F13: 0 | G13: 0 | H13: 0 | I13: 0 | J13: 0 | K13: 24.1 | L13: 4 | M13: 38.9 | N13: 0 | O13: 0 | P13: 0 | Q13: 0 | R13: 0 | S13: 0 | T13: 0 | U13: 0 | V13: 0 | W13: 0 | X13: 0 | Y13: 0 | Z13: 0 | AA13: 0 | AB13: 0 | AC13: 42.4 | AD13: NMR | AE13: =SUM(C13:AB13) -> 100
B14: S464.0(15) | C14: 0 | D14: 14.6 | E14: 23.3 | F14: 0 | G14: 0 | H14: 0 | I14: 0 | J14: 0 | K14: 24.1 | L14: 4 | M14: 34 | N14: 0 | O14: 0 | P14: 0 | Q14: 0 | R14: 0 | S14: 0 | T14: 0 | U14: 0 | V14: 0 | W14: 0 | X14: 0 | Y14: 0 | Z14: 0 | AA14: 0 | AB14: 0 | AC14: 43.2 | AD14: NMR | AE14: =SUM(C14:AB14) -> 100
B15: S464.0(19) | C15: 0 | D15: 19.4 | E15: 23.3 | F15: 0 | G15: 0 | H15: 0 | I15: 0 | J15: 0 | K15: 24.1 | L15: 4 | M15: 29.2 | N15: 0 | O15: 0 | P15: 0 | Q15: 0 | R15: 0 | S15: 0 | T15: 0 | U15: 0 | V15: 0 | W15: 0 | X15: 0 | Y15: 0 | Z15: 0 | AA15: 0 | AB15: 0 | AC15: 43.3 | AD15: NMR | AE15: =SUM(C15:AB15) -> 100
... B17: S464.0(39) | C17: 0 | D17: 38.9 | E17: 23.3 | F17: 0 | G17: 0 | H17: 0 | I17: 0 | J17: 0 | K17: 24.1 | L17: 4 | M17: 9.7 | N17: 0 | O17: 0 | P17: 0 | Q17: 0 | R17: 0 | S17: 0 | T17: 0 | U17: 0 | V17: 0 | W17: 0 | X17: 0 | Y17: 0 | Z17: 0 | AA17: 0 | AB17: 0 | AC17: 41.9 | AD17: NMR | AE17: =SUM(C17:AB17) -> 100
A18: Stevensson, Baltzar, Yang Yu, and Mattias Edén. "Structure–composition trends in multicomponent borosilicate-based glasses deduced from molecular dynamics simulations with improved B–O and P–O force fields." Physical Chemistry Chemical Physics 20.12 (2018): 8192-8209. | B18: BN0.11 | C18: 0 | D18: 90 | E18: 0 | F18: 0 | G18: 0 | H18: 0 | I18: 0 | J18: 0 | K18: 10 | L18: 0 | M18: 0 | N18: 0 | O18: 0 | P18: 0 | Q18: 0 | R18: 0 | S18: 0 | T18: 0 | U18: 0 | V18: 0 | W18: 0 | X18: 0 | Y18: 0 | Z18: 0 | AA18: 0 | AB18: 0 | AC18: 11.6 | AD18: NMR | AE18: =SUM(C18:AB18) -> 100 | AF18: Water quench | AH18: Powder | AI18: Atm.
B19: BN0.20 | C19: 0 | D19: 83 | E19: 0 | F19: 0 | G19: 0 | H19: 0 | I19: 0 | J19: 0 | K19: 17 | L19: 0 | M19: 0 | N19: 0 | O19: 0 | P19: 0 | Q19: 0 | R19: 0 | S19: 0 | T19: 0 | U19: 0 | V19: 0 | W19: 0 | X19: 0 | Y19: 0 | Z19: 0 | AA19: 0 | AB19: 0 | AC19: 22.5 | AD19: NMR | AE19: =SUM(C19:AB19) -> 100
B20: BN0.25 | C20: 0 | D20: 80 | E20: 0 | F20: 0 | G20: 0 | H20: 0 | I20: 0 | J20: 0 | K20: 20 | L20: 0 | M20: 0 | N20: 0 | O20: 0 | P20: 0 | Q20: 0 | R20: 0 | S20: 0 | T20: 0 | U20: 0 | V20: 0 | W20: 0 | X20: 0 | Y20: 0 | Z20: 0 | AA20: 0 | AB20: 0 | AC20: 32 | AD20: NMR | AE20: =SUM(C20:AB20) -> 100
B21: BN0.50 | C21: 0 | D21: 66.7 | E21: 0 | F21: 0 | G21: 0 | H21: 0 | I21: 0 | J21: 0 | K21: 33.3 | L21: 0 | M21: 0 | N21: 0 | O21: 0 | P21: 0 | Q21: 0 | R21: 0 | S21: 0 | T21: 0 | U21: 0 | V21: 0 | W21: 0 | X21: 0 | Y21: 0 | Z21: 0 | AA21: 0 | AB21: 0 | AC21: 43 | AD21: NMR | AE21: =SUM(C21:AB21) -> 100
B22: BN0.67 | C22: 0 | D22: 60 | E22: 0 | F22: 0 | G22: 0 | H22: 0 | I22: 0 | J22: 0 | K22: 40 | L22: 0 | M22: 0 | N22: 0 | O22: 0 | P22: 0 | Q22: 0 | R22: 0 | S22: 0 | T22: 0 | U22: 0 | V22: 0 | W22: 0 | X22: 0 | Y22: 0 | Z22: 0 | AA22: 0 | AB22: 0 | AC22: 43.8 | AD22: NMR | AE22: =SUM(C22:AB22) -> 100
B23: NBS2-0.25(33) | C23: 0 | D23: 30.8 | E23: 0 | F23: 0 | G23: 0 | H23: 0 | I23: 0 | J23: 0 | K23: 7.7 | L23: 0 | M23: 61.5 | N23: 0 | O23: 0 | P23: 0 | Q23: 0 | R23: 0 | S23: 0 | T23: 0 | U23: 0 | V23: 0 | W23: 0 | X23: 0 | Y23: 0 | Z23: 0 | AA23: 0 | AB23: 0 | AC23: 23 | AD23: NMR | AE23: =SUM(C23:AB23) -> 100
B24: NBS2-0.50(33) | C24: 0 | D24: 28.6 | E24: 0 | F24: 0 | G24: 0 | H24: 0 | I24: 0 | J24: 0 | K24: 14.3 | L24: 0 | M24: 57.1 | N24: 0 | O24: 0 | P24: 0 | Q24: 0 | R24: 0 | S24: 0 | T24: 0 | U24: 0 | V24: 0 | W24: 0 | X24: 0 | Y24: 0 | Z24: 0 | AA24: 0 | AB24: 0 | AC24: 45 | AD24: NMR | AE24: =SUM(C24:AB24) -> 100
B25: NBS2-0.75(33) | C25: 0 | D25: 26.7 | E25: 0 | F25: 0 | G25: 0 | H25: 0 | I25: 0 | J25: 0 | K25: 20 | L25: 0 | M25: 53.3 | N25: 0 | O25: 0 | P25: 0 | Q25: 0 | R25: 0 | S25: 0 | T25: 0 | U25: 0 | V25: 0 | W25: 0 | X25: 0 | Y25: 0 | Z25: 0 | AA25: 0 | AB25: 0 | AC25: 58.1 | AD25: NMR | AE25: =SUM(C25:AB25) -> 100
B26: NBS2-2.50(33) | C26: 0 | D26: 18.2 | E26: 0 | F26: 0 | G26: 0 | H26: 0 | I26: 0 | J26: 0 | K26: 45.4 | L26: 0 | M26: 36.4 | N26: 0 | O26: 0 | P26: 0 | Q26: 0 | R26: 0 | S26: 0 | T26: 0 | U26: 0 | V26: 0 | W26: 0 | X26: 0 | Y26: 0 | Z26: 0 | AA26: 0 | AB26: 0 | AC26: 35 | AD26: NMR | AE26: =SUM(C26:AB26) -> 100
B27: NBS0.5-0.50(67) | C27: 0 | D27: 50 | E27: 0 | F27: 0 | G27: 0 | H27: 0 | I27: 0 | J27: 0 | K27: 25 | L27: 0 | M27: 25 | N27: 0 | O27: 0 | P27: 0 | Q27: 0 | R27: 0 | S27: 0 | T27: 0 | U27: 0 | V27: 0 | W27: 0 | X27: 0 | Y27: 0 | Z27: 0 | AA27: 0 | AB27: 0 | AC27: 42 | AD27: NMR | AE27: =SUM(C27:AB27) -> 100
B28: NBS5.10-1.31(16) | C28: 0 | D28: 13.5 | E28: 0 | F28: 0 | G28: 0 | H28: 0 | I28: 0 | J28: 0 | K28: 17.7 | L28: 0 | M28: 68.8 | N28: 0 | O28: 0 | P28: 0 | Q28: 0 | R28: 0 | S28: 0 | T28: 0 | U28: 0 | V28: 0 | W28: 0 | X28: 0 | Y28: 0 | Z28: 0 | AA28: 0 | AB28: 0 | AC28: 83 | AD28: NMR | AE28: =SUM(C28:AB28) -> 100
B29: NBS4-4.00(20) | C29: 0 | D29: 11 | E29: 0 | F29: 0 | G29: 0 | H29: 0 | I29: 0 | J29: 0 | K29: 44.5 | L29: 0 | M29: 44.5 | N29: 0 | O29: 0 | P29: 0 | Q29: 0 | R29: 0 | S29: 0 | T29: 0 | U29: 0 | V29: 0 | W29: 0 | X29: 0 | Y29: 0 | Z29: 0 | AA29: 0 | AB29: 0 | AC29: 38 | AD29: NMR | AE29: =SUM(C29:AB29) -> 100
B30: NCBPS(10) | C30: 0 | D30: 4.9 | E30: 23.3 | F30: 0 | G30: 0 | H30: 0 | I30: 0 | J30: 0 | K30: 24.1 | L30: 4 | M30: 43.7 | N30: 0 | O30: 0 | P30: 0 | Q30: 0 | R30: 0 | S30: 0 | T30: 0 | U30: 0 | V30: 0 | W30: 0 | X30: 0 | Y30: 0 | Z30: 0 | AA30: 0 | AB30: 0 | AC30: 38.8 | AD30: NMR | AE30: =SUM(C30:AB30) -> 100
... B34: NCBPS(80) | C34: 0 | D34: 38.9 | E34: 23.3 | F34: 0 | G34: 0 | H34: 0 | I34: 0 | J34: 0 | K34: 24.1 | L34: 4 | M34: 9.7 | N34: 0 | O34: 0 | P34: 0 | Q34: 0 | R34: 0 | S34: 0 | T34: 0 | U34: 0 | V34: 0 | W34: 0 | X34: 0 | Y34: 0 | Z34: 0 | AA34: 0 | AB34: 0 | AC34: 41.9 | AD34: NMR | AE34: =SUM(C34:AB34) -> 100
A35: Angeli, Frédéric, et al. "Boron speciation in soda‐lime borosilicate glasses containing zirconium." Journal of the American Ceramic Society 93.9 (2010): 2693-2704. | B35: 0Zr10Na | C35: 0 | D35: 17 | E35: 4 | F35: 0 | G35: 0 | H35: 0 | I35: 0 | J35: 0 | K35: 10 | L35: 0 | M35: 69 | N35: 0 | O35: 0 | P35: 0 | Q35: 0 | R35: 0 | S35: 0 | T35: 0 | U35: 0 | V35: 0 | W35: 0 | X35: 0 | Y35: 0 | Z35: 0 | AA35: 0 | AB35: 0 | AC35: 61 | AD35: NMR | AE35: =SUM(C35:AB35) -> 100 | AF35: Air quench | AH35: Powder | AI35: Atm.
B36: 4Zr10Na | C36: 0 | D36: 18 | E36: 4 | F36: 0 | G36: 0 | H36: 0 | I36: 0 | J36: 0 | K36: 10 | L36: 0 | M36: 65 | N36: 0 | O36: 0 | P36: 0 | Q36: 4 | R36: 0 | S36: 0 | T36: 0 | U36: 0 | V36: 0 | W36: 0 | X36: 0 | Y36: 0 | Z36: 0 | AA36: 0 | AB36: 0 | AC36: 47 | AD36: NMR | AE36: =SUM(C36:AB36) -> 101
B37: 0Ca | C37: 0 | D37: 17 | E37: 0 | F37: 0 | G37: 0 | H37: 0 | I37: 0 | J37: 0 | K37: 18 | L37: 0 | M37: 63 | N37: 0 | O37: 0 | P37: 0 | Q37: 2 | R37: 0 | S37: 0 | T37: 0 | U37: 0 | V37: 0 | W37: 0 | X37: 0 | Y37: 0 | Z37: 0 | AA37: 0 | AB37: 0 | AC37: 73 | AD37: NMR | AE37: =SUM(C37:AB37) -> 100
B38: 3Ca | C38: 0 | D38: 16 | E38: 3 | F38: 0 | G38: 0 | H38: 0 | I38: 0 | J38: 0 | K38: 16 | L38: 0 | M38: 63 | N38: 0 | O38: 0 | P38: 0 | Q38: 2 | R38: 0 | S38: 0 | T38: 0 | U38: 0 | V38: 0 | W38: 0 | X38: 0 | Y38: 0 | Z38: 0 | AA38: 0 | AB38: 0 | AC38: 67 | AD38: NMR | AE38: =SUM(C38:AB38) -> 100
B39: 6Ca | C39: 0 | D39: 17 | E39: 6 | F39: 0 | G39: 0 | H39: 0 | I39: 0 | J39: 0 | K39: 13 | L39: 0 | M39: 62 | N39: 0 | O39: 0 | P39: 0 | Q39: 2 | R39: 0 | S39: 0 | T39: 0 | U39: 0 | V39: 0 | W39: 0 | X39: 0 | Y39: 0 | Z39: 0 | AA39: 0 | AB39: 0 | AC39: 61 | AD39: NMR | AE39: =SUM(C39:AB39) -> 100
B40: 9Ca | C40: 0 | D40: 17 | E40: 9 | F40: 0 | G40: 0 | H40: 0 | I40: 0 | J40: 0 | K40: 10 | L40: 0 | M40: 62 | N40: 0 | O40: 0 | P40: 0 | Q40: 2 | R40: 0 | S40: 0 | T40: 0 | U40: 0 | V40: 0 | W40: 0 | X40: 0 | Y40: 0 | Z40: 0 | AA40: 0 | AB40: 0 | AC40: 51 | AD40: NMR | AE40: =SUM(C40:AB40) -> 100
B41: 0Zr | C41: 0 | D41: 17 | E41: 4 | F41: 0 | G41: 0 | H41: 0 | I41: 0 | J41: 0 | K41: 18 | L41: 0 | M41: 61 | N41: 0 | O41: 0 | P41: 0 | Q41: 0 | R41: 0 | S41: 0 | T41: 0 | U41: 0 | V41: 0 | W41: 0 | X41: 0 | Y41: 0 | Z41: 0 | AA41: 0 | AB41: 0 | AC41: 73 | AD41: NMR | AE41: =SUM(C41:AB41) -> 100
B42: 1Zr | C42: 0 | D42: 17 | E42: 4 | F42: 0 | G42: 0 | H42: 0 | I42: 0 | J42: 0 | K42: 18 | L42: 0 | M42: 60 | N42: 0 | O42: 0 | P42: 0 | Q42: 1 | R42: 0 | S42: 0 | T42: 0 | U42: 0 | V42: 0 | W42: 0 | X42: 0 | Y42: 0 | Z42: 0 | AA42: 0 | AB42: 0 | AC42: 71 | AD42: NMR | AE42: =SUM(C42:AB42) -> 100
B43: 2Zr | C43: 0 | D43: 18 | E43: 4 | F43: 0 | G43: 0 | H43: 0 | I43: 0 | J43: 0 | K43: 18 | L43: 0 | M43: 59 | N43: 0 | O43: 0 | P43: 0 | Q43: 2 | R43: 0 | S43: 0 | T43: 0 | U43: 0 | V43: 0 | W43: 0 | X43: 0 | Y43: 0 | Z43: 0 | AA43: 0 | AB43: 0 | AC43: 68 | AD43: NMR | AE43: =SUM(C43:AB43) -> 101
B44: 4Zr | C44: 0 | D44: 18 | E44: 4 | F44: 0 | G44: 0 | H44: 0 | I44: 0 | J44: 0 | K44: 18 | L44: 0 | M44: 57 | N44: 0 | O44: 0 | P44: 0 | Q44: 4 | R44: 0 | S44: 0 | T44: 0 | U44: 0 | V44: 0 | W44: 0 | X44: 0 | Y44: 0 | Z44: 0 | AA44: 0 | AB44: 0 | AC44: 64 | AD44: NMR | AE44: =SUM(C44:AB44) -> 101
...

Sheet 2024 new data
A1: Ref. | B1: Glass ID | C1: Composition (mol%) | AF1: N4 | AH1: sum | AI1: Glass sample preperation details
C2: Al2O3 | D2: B2O3 | E2: CaO | F2: Cr2O3 | G2: Fe2O3 | H2: K2O | I2: Li2O | J2: MgO | K2: Na2O | L2: P2O5 | M2: SiO2 | N2: SO3 | O2: TiO2 | P2: ZnO | Q2: ZrO2 | R2: BaO | S2: Bi2O3 | T2: Cs2O | U2: HfO2 | V2: La2O3 | W2: PbO | X2: SrO | Y2: TeO2 | Z2: Rb2O | AA2: UO3 | AB2: Y2O3 | AC2: SnO2 | AD2: SbO2 | AE2: CoO | AF2: % | AG2: Method | AI2: Cooling rate | AJ2: Annealing | AK2: Sample form | AL2: Pressure | AM2: Note
A3: Bruns S, Uesbeck T, Weil D, Möncke D, van Wüllen L, Durst K and de Ligny D (2020) Influence of Al2O3 Addition on Structure and Mechanical Properties of Borosilicate Glasses. Front. Mater. 7:189. doi: 10.3389/fmats.2020.00189 | B3: 1% Al | C3: 1 | D3: 20.7 | K3: 4.3 | M3: 74 | AF3: 12 | AG3: NMR | AH3: =SUM(C3:AB3) -> 100 | AI3: Furnace cooled (30K/h) | AL3: Atm
B4: 1.5% Al | C4: 1.5 | D4: 20.6 | K4: 4.28 | M4: 73.62 | AF4: 11 | AG4: NMR | AH4: =SUM(C4:AB4) -> 100 | AI4: Furnace cooled (30K/h)
B5: 2% Al | C5: 2 | D5: 20.49 | K5: 4.26 | M5: 73.25 | AF5: 7 | AG5: NMR | AH5: =SUM(C5:AB5) -> 100 | AI5: Furnace cooled (30K/h)
B6: 4% Al | C6: 4 | D6: 20.07 | K6: 4.17 | M6: 71.76 | AF6: 2 | AG6: NMR | AH6: =SUM(C6:AB6) -> 100 | AI6: Furnace cooled (30K/h)
A7: A Chim Lee, Sung Keun Lee, Network polymerization and cation coordination environments in boron-bearing rhyolitic melts: Insights from 17O, 11B, and 27Al solid-state NMR of sodium aluminoborosilicate glasses with varying boron content, Geochimica et Cosmochimica Acta, Volume 268, 2020, Pages 325-347, ISSN 0016-7037, https://doi.org/10.1016/j.gca.2019.10.010. | B7: Lee-XMa0-non-enriched | C7: 25.009157 | D7: 0 | K7: 24.983641 | M7: 50.007202 | AH7: =SUM(C7:AB7) -> 100 | AI7: Cold water quenched | AM7: Unclear if enriched value N4 is reported, but in Fig S3, there is a noticable difference between the two, so I wonder if we can find these values somewhere? 'quenched into glasses'.. Treating as cold water quench based on https://www.sciencedirect.com/topics/engineering/melt-quenching
B8: Lee-XMa0.25-non-enriched | C8: 18.746298 | D8: 6.2445362 | K8: 25.050298 | M8: 49.958868 | AF8: 12 | AG8: NMR | AH8: =SUM(C8:AB8) -> 100 | AI8: Cold water quenched
B9: Lee-Xa0.5-non-enriched | C9: 12.480431 | D9: 12.506714 | K9: 24.962184 | M9: 50.050671 | AF9: 38 | AG9: NMR | AH9: =SUM(C9:AB9) -> 100 | AI9: Cold water quenched
B10: Lee-XMa0.75-non-enriched | C10: 6.2436557 | D10: 18.75568 | K10: 25.049866 | M10: 49.950798 | AF10: 51 | AG10: NMR | AH10: =SUM(C10:AB10) -> 100 | AI10: Cold water quenched
B11: Lee-XMa1-non-enriched | C11: 0 | D11: 25.045061 | K11: 24.983206 | M11: 49.971732 | AF11: 57 | AG11: NMR | AH11: =SUM(C11:AB11) -> 100 | AI11: Cold water quenched
B12: Lee-XMa0-enriched | C12: 24.762304 | D12: 0 | K12: 24.71664 | M12: 50.521055 | AH12: =SUM(C12:AB12) -> 100 | AI12: Cold water quenched
B13: Lee-XMa0.25-enriched | C13: 18.570792 | D13: 6.2310635 | K13: 24.774063 | M13: 50.424082 | AH13: =SUM(C13:AB13) -> 100 | AI13: Cold water quenched
B14: Lee-Xa0.5-enriched | C14: 12.406324 | D14: 12.402091 | K14: 24.729278 | M14: 50.462307 | AH14: =SUM(C14:AB14) -> 100 | AI14: Cold water quenched
B15: Lee-XMa0.75-enriched | C15: 6.1814393 | D15: 18.573547 | K15: 24.741414 | M15: 50.503601 | AH15: =SUM(C15:AB15) -> 100 | AI15: Cold water quenched
B16: Lee-XMa1-enriched | C16: 0 | D16: 24.76157 | K16: 24.767843 | M16: 50.470587 | AH16: =SUM(C16:AB16) -> 100 | AI16: Cold water quenched
B17: Lee-XRd0-non-enriched | C17: 12.484095 | D17: 0 | K17: 12.492 | M17: 75.023905 | AH17: =SUM(C17:AB17) -> 100 | AI17: Cold water quenched
B18: Lee-XRd0.1-non-enriched | C18: 11.244947 | D18: 1.2164996 | K18: 12.507955 | M18: 75.030598 | AH18: =SUM(C18:AB18) -> 100 | AI18: Cold water quenched
B19: Lee-XRd0.25-non-enriched | C19: 9.3686796 | D19: 3.1522415 | K19: 12.49662 | M19: 74.982459 | AF19: 28 | AG19: NMR | AH19: =SUM(C19:AB19) -> 100 | AI19: Cold water quenched
B20: Lee-XRd0.5-non-enriched | C20: 6.2307209 | D20: 6.296675 | K20: 12.505261 | M20: 74.967343 | AF20: 48 | AG20: NMR | AH20: =SUM(C20:AB20) -> 100 | AI20: Cold water quenched
B21: Lee-XRd0.75-non-enriched | C21: 3.1271714 | D21: 9.3398251 | K21: 12.508287 | M21: 75.024717 | AF21: 52 | AG21: NMR | AH21: =SUM(C21:AB21) -> 100 | AI21: Cold water quenched
B22: Lee-XRd1-non-enriched | C22: 0 | D22: 12.534863 | K22: 12.493167 | M22: 74.97197 | AF22: 65 | AG22: NMR | AH22: =SUM(C22:AB22) -> 100 | AI22: Cold water quenched
B23: Lee-XRd0-enriched | C23: 12.317031 | D23: 0 | K23: 12.347678 | M23: 75.335292 | AH23: =SUM(C23:AB23) -> 100 | AI23: Cold water quenched
B24: Lee-XRd0.25-enriched | C24: 9.3683717 | D24: 3.1521379 | K24: 12.392074 | M24: 75.087417 | AH24: =SUM(C24:AB24) -> 100 | AI24: Cold water quenched
B25: Lee-XRd0.5-enriched | C25: 6.2305193 | D25: 6.2964714 | K25: 12.402358 | M25: 75.070652 | AH25: =SUM(C25:AB25) -> 100 | AI25: Cold water quenched
B26: Lee-XRd0.75-enriched | C26: 3.1275175 | D26: 9.4306748 | K26: 12.408787 | M26: 75.033021 | AH26: =SUM(C26:AB26) -> 100 | AI26: Cold water quenched
B27: Lee-XRd1-enriched | C27: 0 | D27: 12.289248 | K27: 12.314107 | M27: 75.396645 | AH27: =SUM(C27:AB27) -> 100 | AI27: Cold water quenched
A28: Jingshi Wu, Timothy M. Gross, Liping Huang, Siva Priya Jaccani, Randall E. Youngman, Sylwester J. Rzoska, Michal Bockowski, Saurav Bista, Jonathan F. Stebbins, Morten M. Smedskjaer, Composition and pressure effects on the structure, elastic properties and hardness of aluminoborosilicate glass, Journal of Non-Crystalline Solids, Volume 530, 2020, 119797, ISSN 0022-3093, https://doi.org/10.1016/j.jnoncrysol.2019.119797. | B28: CABS5-0.0001GPa | C28: 14.99 | D28: 4.79 | E28: 15 | M28: 65.22 | AF28: 2.7 | AG28: NMR | AH28: =SUM(C28:AB28) -> 100 | AI28: Cold water quenched | AJ28: 783°C | AL28: 0.0001Gpa | AM28: Annealing temp is holding temp for compression experiments. Annealed for 4 hours to reduce thermal stress, beam-bending viscometer measurement made, then annealed for 24h to reach structural equilibrium
B29: CABS5-1GPa | C29: 14.99 | D29: 4.79 | E29: 15 | M29: 65.22 | AF29: 7 | AG29: NMR | AH29: =SUM(C29:AB29) -> 100 | AI29: Cold water quenched | AJ29: 795°C | AL29: 1GPa
B30: CABS5-2GPa | C30: 14.99 | D30: 4.79 | E30: 15 | M30: 65.22 | AF30: 11.7 | AG30: NMR | AH30: =SUM(C30:AB30) -> 100 | AI30: Cold water quenched | AJ30: 810°C | AL30: 2 Gpa
B31: CABS10-0.0001GPa | C31: 15.06 | D31: 9.59 | E31: 15.21 | M31: 60.14 | AF31: 3.6 | AG31: NMR | AH31: =SUM(C31:AB31) -> 100 | AI31: Cold water quenched | AJ31: 740°C | AL31: 0.0001Gpa
B32: CABS10-1GPa | C32: 15.06 | D32: 9.59 | E32: 15.21 | M32: 60.14 | AF32: 8 | AG32: NMR | AH32: =SUM(C32:AB32) -> 100 | AI32: Cold water quenched | AJ32: 745°C | AL32: 1GPa
B33: CABS10-2GPa | C33: 15.06 | D33: 9.59 | E33: 15.21 | M33: 60.14 | AF33: 16.3 | AG33: NMR | AH33: =SUM(C33:AB33) -> 100 | AI33: Cold water quenched | AJ33: 760°C | AL33: 2 Gpa
B34: CABS15-0.0001GPa | C34: 15.06 | D34: 14.28 | E34: 15.21 | M34: 55.45 | AF34: 4.4 | AG34: NMR | AH34: =SUM(C34:AB34) -> 100 | AI34: Cold water quenched | AJ34: 710°C | AL34: 0.0001Gpa
B35: CABS15-1GPa | C35: 15.06 | D35: 14.28 | E35: 15.21 | M35: 55.45 | AF35: 9.1 | AG35: NMR | AH35: =SUM(C35:AB35) -> 100 | AI35: Cold water quenched | AJ35: 720°C | AL35: 1GPa
B36: CABS15-2GPa | C36: 15.06 | D36: 14.28 | E36: 15.21 | M36: 55.45 | AF36: 17 | AG36: NMR | AH36: =SUM(C36:AB36) -> 100 | AI36: Cold water quenched | AJ36: 740°C | AL36: 2 Gpa
B37: CABS20-0.0001GPa | C37: 15.05 | D37: 18.99 | E37: 15.14 | M37: 50.82 | AF37: 5.7 | AG37: NMR | AH37: =SUM(C37:AB37) -> 100 | AI37: Cold water quenched | AJ37: 681°C | AL37: 0.0001Gpa
B38: CABS20-1GPa | C38: 15.05 | D38: 18.99 | E38: 15.14 | M38: 50.82 | AF38: 11.2 | AG38: NMR | AH38: =SUM(C38:AB38) -> 100 | AI38: Cold water quenched | AJ38: 690°C | AL38: 1GPa
B39: CABS20-2GPa | C39: 15.05 | D39: 18.99 | E39: 15.14 | M39: 50.82 | AF39: 18.2 | AG39: NMR | AH39: =SUM(C39:AB39) -> 100 | AI39: Cold water quenched | AJ39: 720°C | AL39: 2 Gpa
B40: CABS25-0.0001GPa | C40: 15.05 | D40: 23.5 | E40: 15.11 | M40: 46.34 | AF40: 6.4 | AG40: NMR | AH40: =SUM(C40:AB40) -> 100 | AI40: Cold water quenched | AJ40: 657°C | AL40: 0.0001Gpa
...

Sheet 2024 wt to mol conversion
C1: B2O3 | D1: SiO2 | E1: Na2O | F1: Al2O3 | G1: FeO | I1: SiO2 | J1: Al2O3 | K1: B2O3 | L1: MgO | M1: CaO | N1: Sr0 | O1: ZnO | P1: SnO2 | Q1: Sb2O3
B2: Molar weight (IUPAC 2018) | C2: 69.617 | D2: 60.083 | E2: 61.979 | F2: 101.9622 | G2: 71.844 | I2: 60.083 | J2: 101.9622 | K2: 69.617 | L2: 40.304 | M2: 56.077 | N2: 103.6194 | O2: 81.379 | P2: 150.7088 | Q2: 91.52
A4: Ref | B4: Glass ID
A5: A Chim Lee, Sung Keun Lee, Network polymerization and cation coordination environments in boron-bearing rhyolitic melts: Insights from 17O, 11B, and 27Al solid-state NMR of sodium aluminoborosilicate glasses with varying boron content, Geochimica et Cosmochimica Acta, Volume 268, 2020, Pages 325-347, ISSN 0016-7037, https://doi.org/10.1016/j.gca.2019.10.010. | B5: wt % | C5: B2O3 | D5: SiO2 | E5: Na2O | F5: Al2O3 | G5: sum | H5: mol% | I5: B2O3 | J5: SiO2 | K5: Na2O | L5: Al2O3 | N5: sum
B6: Lee-XMa0-non-enriched | C6: 0 | D6: 42.3 | E6: 21.8 | F6: 35.9 | G6: =SUM(C6:F6) -> 100 | H6: Lee-XMa0-non-enriched | I6: {=C6/C$2/SUMPRODUCT(1/($C$2:$F$2),$C6:$F6)*100} -> 0 | J6: {=D6/D$2/SUMPRODUCT(1/($C$2:$F$2),$C6:$F6)*100} -> 50.007202 | K6: {=E6/E$2/SUMPRODUCT(1/($C$2:$F$2),$C6:$F6)*100} -> 24.983641 | L6: {=F6/F$2/SUMPRODUCT(1/($C$2:$F$2),$C6:$F6)*100} -> 25.009157 | N6: =SUM(I6:L6) -> 100
B7: Lee-XMa0.25-non-enriched | C7: 6.3 | D7: 43.5 | E7: 22.5 | F7: 27.7 | G7: =SUM(C7:F7) -> 100 | H7: Lee-XMa0.25-non-enriched | I7: {=C7/C$2/SUMPRODUCT(1/($C$2:$F$2),$C7:$F7)*100} -> 6.2445362 | J7: {=D7/D$2/SUMPRODUCT(1/($C$2:$F$2),$C7:$F7)*100} -> 49.958868 | K7: {=E7/E$2/SUMPRODUCT(1/($C$2:$F$2),$C7:$F7)*100} -> 25.050298 | L7: {=F7/F$2/SUMPRODUCT(1/($C$2:$F$2),$C7:$F7)*100} -> 18.746298 | N7: =SUM(I7:L7) -> 100
B8: Lee-Xa0.5-non-enriched | C8: 13 | D8: 44.9 | E8: 23.1 | F8: 19 | G8: =SUM(C8:F8) -> 100 | H8: Lee-Xa0.5-non-enriched | I8: {=C8/C$2/SUMPRODUCT(1/($C$2:$F$2),$C8:$F8)*100} -> 12.506714 | J8: {=D8/D$2/SUMPRODUCT(1/($C$2:$F$2),$C8:$F8)*100} -> 50.050671 | K8: {=E8/E$2/SUMPRODUCT(1/($C$2:$F$2),$C8:$F8)*100} -> 24.962184 | L8: {=F8/F$2/SUMPRODUCT(1/($C$2:$F$2),$C8:$F8)*100} -> 12.480431 | N8: =SUM(I8:L8) -> 100
B9: Lee-XMa0.75-non-enriched | C9: 20.1 | D9: 46.2 | E9: 23.9 | F9: 9.8 | G9: =SUM(C9:F9) -> 100 | H9: Lee-XMa0.75-non-enriched | I9: {=C9/C$2/SUMPRODUCT(1/($C$2:$F$2),$C9:$F9)*100} -> 18.75568 | J9: {=D9/D$2/SUMPRODUCT(1/($C$2:$F$2),$C9:$F9)*100} -> 49.950798 | K9: {=E9/E$2/SUMPRODUCT(1/($C$2:$F$2),$C9:$F9)*100} -> 25.049866 | L9: {=F9/F$2/SUMPRODUCT(1/($C$2:$F$2),$C9:$F9)*100} -> 6.2436557 | N9: =SUM(I9:L9) -> 100
B10: Lee-XMa1-non-enriched | C10: 27.7 | D10: 47.7 | E10: 24.6 | F10: 0 | G10: =SUM(C10:F10) -> 100 | H10: Lee-XMa1-non-enriched | I10: {=C10/C$2/SUMPRODUCT(1/($C$2:$F$2),$C10:$F10)*100} -> 25.045061 | J10: {=D10/D$2/SUMPRODUCT(1/($C$2:$F$2),$C10:$F10)*100} -> 49.971732 | K10: {=E10/E$2/SUMPRODUCT(1/($C$2:$F$2),$C10:$F10)*100} -> 24.983206 | L10: {=F10/F$2/SUMPRODUCT(1/($C$2:$F$2),$C10:$F10)*100} -> 0 | N10: =SUM(I10:L10) -> 100
B11: Lee-XMa0-enriched | C11: 0 | D11: 42.8 | E11: 21.6 | F11: 35.6 | G11: =SUM(C11:F11) -> 100 | H11: Lee-XMa0-enriched | I11: {=C11/C$2/SUMPRODUCT(1/($C$2:$F$2),$C11:$F11)*100} -> 0 | J11: {=D11/D$2/SUMPRODUCT(1/($C$2:$F$2),$C11:$F11)*100} -> 50.521055 | K11: {=E11/E$2/SUMPRODUCT(1/($C$2:$F$2),$C11:$F11)*100} -> 24.71664 | L11: {=F11/F$2/SUMPRODUCT(1/($C$2:$F$2),$C11:$F11)*100} -> 24.762304 | N11: =SUM(I11:L11) -> 100
B12: Lee-XMa0.25-enriched | C12: 6.3 | D12: 44 | E12: 22.3 | F12: 27.5 | G12: =SUM(C12:F12) -> 100.1 | H12: Lee-XMa0.25-enriched | I12: {=C12/C$2/SUMPRODUCT(1/($C$2:$F$2),$C12:$F12)*100} -> 6.2310635 | J12: {=D12/D$2/SUMPRODUCT(1/($C$2:$F$2),$C12:$F12)*100} -> 50.424082 | K12: {=E12/E$2/SUMPRODUCT(1/($C$2:$F$2),$C12:$F12)*100} -> 24.774063 | L12: {=F12/F$2/SUMPRODUCT(1/($C$2:$F$2),$C12:$F12)*100} -> 18.570792 | N12: =SUM(I12:L12) -> 100
B13: Lee-Xa0.5-enriched | C13: 12.9 | D13: 45.3 | E13: 22.9 | F13: 18.9 | G13: =SUM(C13:F13) -> 100 | H13: Lee-Xa0.5-enriched | I13: {=C13/C$2/SUMPRODUCT(1/($C$2:$F$2),$C13:$F13)*100} -> 12.402091 | J13: {=D13/D$2/SUMPRODUCT(1/($C$2:$F$2),$C13:$F13)*100} -> 50.462307 | K13: {=E13/E$2/SUMPRODUCT(1/($C$2:$F$2),$C13:$F13)*100} -> 24.729278 | L13: {=F13/F$2/SUMPRODUCT(1/($C$2:$F$2),$C13:$F13)*100} -> 12.406324 | N13: =SUM(I13:L13) -> 100
B14: Lee-XMa0.75-enriched | C14: 19.9 | D14: 46.7 | E14: 23.6 | F14: 9.7 | G14: =SUM(C14:F14) -> 99.9 | H14: Lee-XMa0.75-enriched | I14: {=C14/C$2/SUMPRODUCT(1/($C$2:$F$2),$C14:$F14)*100} -> 18.573547 | J14: {=D14/D$2/SUMPRODUCT(1/($C$2:$F$2),$C14:$F14)*100} -> 50.503601 | K14: {=E14/E$2/SUMPRODUCT(1/($C$2:$F$2),$C14:$F14)*100} -> 24.741414 | L14: {=F14/F$2/SUMPRODUCT(1/($C$2:$F$2),$C14:$F14)*100} -> 6.1814393 | N14: =SUM(I14:L14) -> 100
B15: Lee-XMa1-enriched | C15: 27.4 | D15: 48.2 | E15: 24.4 | F15: 0 | G15: =SUM(C15:F15) -> 100 | H15: Lee-XMa1-enriched | I15: {=C15/C$2/SUMPRODUCT(1/($C$2:$F$2),$C15:$F15)*100} -> 24.76157 | J15: {=D15/D$2/SUMPRODUCT(1/($C$2:$F$2),$C15:$F15)*100} -> 50.470587 | K15: {=E15/E$2/SUMPRODUCT(1/($C$2:$F$2),$C15:$F15)*100} -> 24.767843 | L15: {=F15/F$2/SUMPRODUCT(1/($C$2:$F$2),$C15:$F15)*100} -> 0 | N15: =SUM(I15:L15) -> 100
B16: Lee-XRd0-non-enriched | C16: 0 | D16: 68.7 | E16: 11.8 | F16: 19.4 | G16: =SUM(C16:F16) -> 99.9 | H16: Lee-XRd0-non-enriched | I16: {=C16/C$2/SUMPRODUCT(1/($C$2:$F$2),$C16:$F16)*100} -> 0 | J16: {=D16/D$2/SUMPRODUCT(1/($C$2:$F$2),$C16:$F16)*100} -> 75.023905 | K16: {=E16/E$2/SUMPRODUCT(1/($C$2:$F$2),$C16:$F16)*100} -> 12.492 | L16: {=F16/F$2/SUMPRODUCT(1/($C$2:$F$2),$C16:$F16)*100} -> 12.484095 | N16: =SUM(I16:L16) -> 100
B17: Lee-XRd0.1-non-enriched | C17: 1.3 | D17: 69.2 | E17: 11.9 | F17: 17.6 | G17: =SUM(C17:F17) -> 100 | H17: Lee-XRd0.1-non-enriched | I17: {=C17/C$2/SUMPRODUCT(1/($C$2:$F$2),$C17:$F17)*100} -> 1.2164996 | J17: {=D17/D$2/SUMPRODUCT(1/($C$2:$F$2),$C17:$F17)*100} -> 75.030598 | K17: {=E17/E$2/SUMPRODUCT(1/($C$2:$F$2),$C17:$F17)*100} -> 12.507955 | L17: {=F17/F$2/SUMPRODUCT(1/($C$2:$F$2),$C17:$F17)*100} -> 11.244947 | N17: =SUM(I17:L17) -> 100
... B26: Lee-XRd1-enriched | C26: 13.9 | D26: 73.6 | E26: 12.4 | F26: 0 | G26: =SUM(C26:F26) -> 99.9 | H26: Lee-XRd1-enriched | I26: {=C26/C$2/SUMPRODUCT(1/($C$2:$F$2),$C26:$F26)*100} -> 12.289248 | J26: {=D26/D$2/SUMPRODUCT(1/($C$2:$F$2),$C26:$F26)*100} -> 75.396645 | K26: {=E26/E$2/SUMPRODUCT(1/($C$2:$F$2),$C26:$F26)*100} -> 12.314107 | L26: {=F26/F$2/SUMPRODUCT(1/($C$2:$F$2),$C26:$F26)*100} -> 0 | N26: =SUM(I26:L26) -> 100
A28: ref | B28: wt% | C28: SiO2 | D28: Al2O3 | E28: B2O3 | F28: MgO | G28: CaO | H28: SrO | I28: ZnO | J28: SnO2 | K28: Sb2O3 | L28: SUM | N28: mol% | O28: SiO2 | P28: Al2O3 | Q28: B2O3 | R28: MgO | S28: CaO | T28: SrO | U28: ZnO | V28: SnO2 | W28: Sb2O3 | X28: SUM
A29: Qianxing Huang, Jianlei Liu, Xi He, Taoyong Liu, Anxian Lu, Analysis of structure evolution and performance in alkali-free glass substrates via XPS and infrared: Boron-aluminum anomaly, Journal of Non-Crystalline Solids, Volume 555, 2021, 120531, ISSN 0022-3093, https://doi.org/10.1016/j.jnoncrysol.2020.120531. | B29: DPG0 | C29: 58.2 | D29: 21.8 | E29: 0 | F29: 4.7 | G29: 5.8 | H29: 8 | I29: 0.85 | J29: 0.2 | K29: 0.45 | L29: =SUM(C29:K29) -> 100 | N29: DPG0 | O29: {=C29/I$2/(SUMPRODUCT(1/$I$2:$Q$2,$C29:$K29))*100} -> 64.732594 | P29: {=D29/J$2/(SUMPRODUCT(1/$I$2:$Q$2,$C29:$K29))*100} -> 14.287917 | Q29: {=E29/K$2/(SUMPRODUCT(1/$I$2:$Q$2,$C29:$K29))*100} -> 0 | R29: {=F29/L$2/(SUMPRODUCT(1/$I$2:$Q$2,$C29:$K29))*100} -> 7.7929402 | S29: {=G29/M$2/(SUMPRODUCT(1/$I$2:$Q$2,$C29:$K29))*100} -> 6.9118588 | T29: {=H29/N$2/(SUMPRODUCT(1/$I$2:$Q$2,$C29:$K29))*100} -> 5.159416 | U29: {=I29/O$2/(SUMPRODUCT(1/$I$2:$Q$2,$C29:$K29))*100} -> 0.69800448 | V29: {=J29/P$2/(SUMPRODUCT(1/$I$2:$Q$2,$C29:$K29))*100} -> 0.08868354 | W29: {=K29/Q$2/(SUMPRODUCT(1/$I$2:$Q$2,$C29:$K29))*100} -> 0.32858531 | X29: =SUM(O29:W29) -> 100
B30: DPG2 | C30: 58.2 | D30: 19.8 | E30: 2 | F30: 4.7 | G30: 5.8 | H30: 8 | I30: 0.85 | J30: 0.2 | K30: 0.45 | L30: =SUM(C30:K30) -> 100 | N30: DPG2 | O30: {=C30/I$2/(SUMPRODUCT(1/$I$2:$Q$2,$C30:$K30))*100} -> 64.340741 | P30: {=D30/J$2/(SUMPRODUCT(1/$I$2:$Q$2,$C30:$K30))*100} -> 12.898544 | Q30: {=E30/K$2/(SUMPRODUCT(1/$I$2:$Q$2,$C30:$K30))*100} -> 1.9082241 | R30: {=F30/L$2/(SUMPRODUCT(1/$I$2:$Q$2,$C30:$K30))*100} -> 7.7457664 | S30: {=G30/M$2/(SUMPRODUCT(1/$I$2:$Q$2,$C30:$K30))*100} -> 6.8700185 | T30: {=H30/N$2/(SUMPRODUCT(1/$I$2:$Q$2,$C30:$K30))*100} -> 5.128184 | U30: {=I30/O$2/(SUMPRODUCT(1/$I$2:$Q$2,$C30:$K30))*100} -> 0.69377918 | V30: {=J30/P$2/(SUMPRODUCT(1/$I$2:$Q$2,$C30:$K30))*100} -> 0.088146702 | W30: {=K30/Q$2/(SUMPRODUCT(1/$I$2:$Q$2,$C30:$K30))*100} -> 0.32659624 | X30: =SUM(O30:W30) -> 100
B31: DPG4 | C31: 58.2 | D31: 17.8 | E31: 4 | F31: 4.7 | G31: 5.8 | H31: 8 | I31: 0.85 | J31: 0.2 | K31: 0.45 | L31: =SUM(C31:K31) -> 100 | N31: DPG4 | O31: {=C31/I$2/(SUMPRODUCT(1/$I$2:$Q$2,$C31:$K31))*100} -> 63.953604 | P31: {=D31/J$2/(SUMPRODUCT(1/$I$2:$Q$2,$C31:$K31))*100} -> 11.52589 | Q31: {=E31/K$2/(SUMPRODUCT(1/$I$2:$Q$2,$C31:$K31))*100} -> 3.7934847 | R31: {=F31/L$2/(SUMPRODUCT(1/$I$2:$Q$2,$C31:$K31))*100} -> 7.6991602 | S31: {=G31/M$2/(SUMPRODUCT(1/$I$2:$Q$2,$C31:$K31))*100} -> 6.8286817 | T31: {=H31/N$2/(SUMPRODUCT(1/$I$2:$Q$2,$C31:$K31))*100} -> 5.0973278 | U31: {=I31/O$2/(SUMPRODUCT(1/$I$2:$Q$2,$C31:$K31))*100} -> 0.68960472 | V31: {=J31/P$2/(SUMPRODUCT(1/$I$2:$Q$2,$C31:$K31))*100} -> 0.087616325 | W31: {=K31/Q$2/(SUMPRODUCT(1/$I$2:$Q$2,$C31:$K31))*100} -> 0.32463112 | X31: =SUM(O31:W31) -> 100
B32: DOG6 | C32: 58.2 | D32: 15.8 | E32: 6 | F32: 4.7 | G32: 5.8 | H32: 8 | I32: 0.85 | J32: 0.2 | K32: 0.45 | L32: =SUM(C32:K32) -> 100 | N32: DPG6 | O32: {=C32/I$2/(SUMPRODUCT(1/$I$2:$Q$2,$C32:$K32))*100} -> 63.571098 | P32: {=D32/J$2/(SUMPRODUCT(1/$I$2:$Q$2,$C32:$K32))*100} -> 10.169655 | Q32: {=E32/K$2/(SUMPRODUCT(1/$I$2:$Q$2,$C32:$K32))*100} -> 5.6561938 | R32: {=F32/L$2/(SUMPRODUCT(1/$I$2:$Q$2,$C32:$K32))*100} -> 7.6531115 | S32: {=G32/M$2/(SUMPRODUCT(1/$I$2:$Q$2,$C32:$K32))*100} -> 6.7878394 | T32: {=H32/N$2/(SUMPRODUCT(1/$I$2:$Q$2,$C32:$K32))*100} -> 5.0668407 | U32: {=I32/O$2/(SUMPRODUCT(1/$I$2:$Q$2,$C32:$K32))*100} -> 0.68548019 | V32: {=J32/P$2/(SUMPRODUCT(1/$I$2:$Q$2,$C32:$K32))*100} -> 0.087092292 | W32: {=K32/Q$2/(SUMPRODUCT(1/$I$2:$Q$2,$C32:$K32))*100} -> 0.3226895 | X32: =SUM(O32:W32) -> 100
B33: DPG8 | C33: 58.2 | D33: 13.8 | E33: 8 | F33: 4.7 | G33: 5.8 | H33: 8 | I33: 0.85 | J33: 0.2 | K33: 0.45 | L33: =SUM(C33:K33) -> 100 | N33: DPG8 | O33: {=C33/I$2/(SUMPRODUCT(1/$I$2:$Q$2,$C33:$K33))*100} -> 63.19314 | P33: {=D33/J$2/(SUMPRODUCT(1/$I$2:$Q$2,$C33:$K33))*100} -> 8.8295475 | Q33: {=E33/K$2/(SUMPRODUCT(1/$I$2:$Q$2,$C33:$K33))*100} -> 7.4967536 | R33: {=F33/L$2/(SUMPRODUCT(1/$I$2:$Q$2,$C33:$K33))*100} -> 7.6076104 | S33: {=G33/M$2/(SUMPRODUCT(1/$I$2:$Q$2,$C33:$K33))*100} -> 6.7474827 | T33: {=H33/N$2/(SUMPRODUCT(1/$I$2:$Q$2,$C33:$K33))*100} -> 5.0367161 | U33: {=I33/O$2/(SUMPRODUCT(1/$I$2:$Q$2,$C33:$K33))*100} -> 0.68140471 | V33: {=J33/P$2/(SUMPRODUCT(1/$I$2:$Q$2,$C33:$K33))*100} -> 0.08657449 | W33: {=K33/Q$2/(SUMPRODUCT(1/$I$2:$Q$2,$C33:$K33))*100} -> 0.32077097 | X33: =SUM(O33:W33) -> 100
A39: [(77 – x) B2O3 –x ZnO 22.7 Na2O– 0.3 CoO]
A40: 0 | B40: =77-0 -> 77 | C40: =77-A41 -> 72
A41: 5 | B41: 0 | C41: =A41 -> 5
A42: 10 | B42: 22.7
A43: 15 | B43: 0.3
A44: 20

Sheet EWG-CCP-127 (1)
C1: B2O3 | D1: SiO2 | E1: Na2O | F1: FeO | G1: Al2O3 | H1: B2O3 | I1: CaO | J1: Cr2O3 | K1: Fe2O3 | L1: K2O | M1: La2O3 | N1: MgO | O1: Na2O | P1: P2O5 | Q1: SO3 | R1: SiO2 | S1: TiO2 | T1: ZnO | U1: ZrO2 | V1: Li2O
B2: Molar weight (IUPAC 2018) | C2: =10.81*2+15.999*3 -> 69.617 | D2: =28.085+15.999*2 -> 60.083 | E2: =22.99*2+15.999 -> 61.979 | F2: =55.845+15.999 -> 71.844 | G2: =26.982*2+15.9994*3 -> 101.9622 | H2: =10.81*2+15.999*3 -> 69.617 | I2: =40.078+15.999 -> 56.077 | J2: =51.996*2+15.999*3 -> 151.989 | K2: =55.845*2+15.999*3 -> 159.687 | L2: =39.098*2+15.999 -> 94.195 | M2: =138.91*2+15.999*3 -> 325.817 | N2: =24.305+15.999 -> 40.304 | O2: =22.99*2+15.999 -> 61.979 | P2: =30.974*2+15.999*5 -> 141.943 | Q2: =32.06+15.999*3 -> 80.057 | R2: =28.085+15.999*2 -> 60.083 | S2: =47.867+15.999*2 -> 79.865 | T2: =65.38+15.999 -> 81.379 | U2: =91.224+15.999*2 -> 123.222 | V2: =6.94*2+15.999 -> 29.879
B4: wt% | C4: B2O3 | D4: SiO2 | E4: Na2O | F4: FeO | H4: mol% | I4: B2O3 | J4: SiO2 | K4: Na2O | L4: FeO | M4: SUM
A5: Cochain, B., et al. "Effects of the Iron Content and Redox State on the Structure of Sodium Borosilicate Glasses: AR aman, M össbauer and Boron K‐Edge XANES Spectroscopy Study." Journal of the American Ceramic Society 95.3 (2012): 962-971. | B5: NBF67.18.0 | C5: 19.36 | D5: 66.9 | E5: 13.65 | F5: 0 | H5: NBF67.18.0 | I5: {=C5/C$2/SUMPRODUCT(1/($C$2:$F$2),$C5:$F5)*100} -> 17.253689 | J5: =D5/D$2/SUMPRODUCT(1/($C$2:$F$2),$C5:$F5)*100 -> 69.082243 | K5: =E5/E$2/SUMPRODUCT(1/($C$2:$F$2),$C5:$F5)*100 -> 13.664068 | L5: =F5/F$2/SUMPRODUCT(1/($C$2:$F$2),$C5:$F5)*100 -> 0 | M5: =SUM(I5:L5) -> 100
B6: NBF67.18.1 | C6: 19.49 | D6: 64.46 | E6: 12.31 | F6: 1.19 | H6: NBF67.18.1 | I6: =C6/C$2/SUMPRODUCT(1/($C$2:$F$2),$C6:$F6)*100 -> 17.854741 | J6: =D6/D$2/SUMPRODUCT(1/($C$2:$F$2),$C6:$F6)*100 -> 68.421991 | K6: =E6/E$2/SUMPRODUCT(1/($C$2:$F$2),$C6:$F6)*100 -> 12.666905 | L6: =F6/F$2/SUMPRODUCT(1/($C$2:$F$2),$C6:$F6)*100 -> 1.0563637 | M6: =SUM(I6:L6) -> 100
B7: NBF67.18.1-R5 | C7: 20.01 | D7: 64.66 | E7: 13.05 | F7: 1.14 | H7: NBF67.18.1-R5 | I7: =C7/C$2/SUMPRODUCT(1/($C$2:$F$2),$C7:$F7)*100 -> 18.076997 | J7: =D7/D$2/SUMPRODUCT(1/($C$2:$F$2),$C7:$F7)*100 -> 67.682843 | K7: =E7/E$2/SUMPRODUCT(1/($C$2:$F$2),$C7:$F7)*100 -> 13.242209 | L7: =F7/F$2/SUMPRODUCT(1/($C$2:$F$2),$C7:$F7)*100 -> 0.99795016 | M7: =SUM(I7:L7) -> 100
B8: NBF67.18.1-R12 | C8: 19.94 | D8: 63.87 | E8: 12.77 | F8: 1.16 | H8: NBF67.18.1-R12 | I8: =C8/C$2/SUMPRODUCT(1/($C$2:$F$2),$C8:$F8)*100 -> 18.224579 | J8: =D8/D$2/SUMPRODUCT(1/($C$2:$F$2),$C8:$F8)*100 -> 67.638342 | K8: =E8/E$2/SUMPRODUCT(1/($C$2:$F$2),$C8:$F8)*100 -> 13.109737 | L8: =F8/F$2/SUMPRODUCT(1/($C$2:$F$2),$C8:$F8)*100 -> 1.0273422 | M8: =SUM(I8:L8) -> 100
B9: NBF67.18.5-800 | C9: 19.84 | D9: 61.82 | E9: 12.88 | F9: 5.45 | H9: NBF67.18.5-800 | I9: =C9/C$2/SUMPRODUCT(1/($C$2:$F$2),$C9:$F9)*100 -> 17.838845 | J9: =D9/D$2/SUMPRODUCT(1/($C$2:$F$2),$C9:$F9)*100 -> 64.40473 | K9: =E9/E$2/SUMPRODUCT(1/($C$2:$F$2),$C9:$F9)*100 -> 13.008034 | L9: =F9/F$2/SUMPRODUCT(1/($C$2:$F$2),$C9:$F9)*100 -> 4.7483899 | M9: =SUM(I9:L9) -> 100
B10: NBF67.18.5-700 | C10: 18.93 | D10: 62.03 | E10: 11.75 | F10: 5.77 | H10: NBF67.18.5-700 | I10: =C10/C$2/SUMPRODUCT(1/($C$2:$F$2),$C10:$F10)*100 -> 17.273141 | J10: =D10/D$2/SUMPRODUCT(1/($C$2:$F$2),$C10:$F10)*100 -> 65.582232 | K10: =E10/E$2/SUMPRODUCT(1/($C$2:$F$2),$C10:$F10)*100 -> 12.042851 | L10: =F10/F$2/SUMPRODUCT(1/($C$2:$F$2),$C10:$F10)*100 -> 5.1017753 | M10: =SUM(I10:L10) -> 100
B11: NBF67.18.5 | C11: 19.57 | D11: 61.78 | E11: 12.99 | F11: 5.74 | H11: NBF67.18.5 | I11: =C11/C$2/SUMPRODUCT(1/($C$2:$F$2),$C11:$F11)*100 -> 17.582132 | J11: =D11/D$2/SUMPRODUCT(1/($C$2:$F$2),$C11:$F11)*100 -> 64.312045 | K11: =E11/E$2/SUMPRODUCT(1/($C$2:$F$2),$C11:$F11)*100 -> 13.10873 | L11: =F11/F$2/SUMPRODUCT(1/($C$2:$F$2),$C11:$F11)*100 -> 4.9970928 | M11: =SUM(I11:L11) -> 100
B12: NBF67.18.5-R5 | C12: 18.73 | D12: 62.09 | E12: 12.76 | F12: 5.66 | H12: NBF67.18.5-R5 | I12: =C12/C$2/SUMPRODUCT(1/($C$2:$F$2),$C12:$F12)*100 -> 16.951836 | J12: =D12/D$2/SUMPRODUCT(1/($C$2:$F$2),$C12:$F12)*100 -> 65.112492 | K12: =E12/E$2/SUMPRODUCT(1/($C$2:$F$2),$C12:$F12)*100 -> 12.971804 | L12: =F12/F$2/SUMPRODUCT(1/($C$2:$F$2),$C12:$F12)*100 -> 4.9638677 | M12: =SUM(I12:L12) -> 100
B13: NBF67.18.5-R9 | C13: 19.01 | D13: 61.31 | E13: 12.23 | F13: 5.88 | H13: NBF67.18.5-R9 | I13: =C13/C$2/SUMPRODUCT(1/($C$2:$F$2),$C13:$F13)*100 -> 17.363331 | J13: =D13/D$2/SUMPRODUCT(1/($C$2:$F$2),$C13:$F13)*100 -> 64.885243 | K13: =E13/E$2/SUMPRODUCT(1/($C$2:$F$2),$C13:$F13)*100 -> 12.547238 | L13: =F13/F$2/SUMPRODUCT(1/($C$2:$F$2),$C13:$F13)*100 -> 5.2041889 | M13: =SUM(I13:L13) -> 100
B14: NBF67.18.5-R15 | C14: 18.84 | D14: 62 | E14: 11.98 | F14: 5.74 | H14: NBF67.18.5-R15 | I14: =C14/C$2/SUMPRODUCT(1/($C$2:$F$2),$C14:$F14)*100 -> 17.17464 | J14: =D14/D$2/SUMPRODUCT(1/($C$2:$F$2),$C14:$F14)*100 -> 65.488061 | K14: =E14/E$2/SUMPRODUCT(1/($C$2:$F$2),$C14:$F14)*100 -> 12.266885 | L14: =F14/F$2/SUMPRODUCT(1/($C$2:$F$2),$C14:$F14)*100 -> 5.0704142 | M14: =SUM(I14:L14) -> 100
B15: NBF67.18.5-R17 | C15: 19.07 | D15: 62.81 | E15: 12.83 | F15: 5.6 | H15: NBF67.18.5-R17 | I15: =C15/C$2/SUMPRODUCT(1/($C$2:$F$2),$C15:$F15)*100 -> 17.074924 | J15: =D15/D$2/SUMPRODUCT(1/($C$2:$F$2),$C15:$F15)*100 -> 65.162927 | K15: =E15/E$2/SUMPRODUCT(1/($C$2:$F$2),$C15:$F15)*100 -> 12.90344 | L15: =F15/F$2/SUMPRODUCT(1/($C$2:$F$2),$C15:$F15)*100 -> 4.8587094 | M15: =SUM(I15:L15) -> 100
B16: NBF67.18.10-800 | C16: 18 | D16: 58.38 | E16: 10.74 | F16: 11.4 | H16: NBF67.18.10-800 | I16: =C16/C$2/SUMPRODUCT(1/($C$2:$F$2),$C16:$F16)*100 -> 16.551124 | J16: =D16/D$2/SUMPRODUCT(1/($C$2:$F$2),$C16:$F16)*100 -> 62.198912 | K16: =E16/E$2/SUMPRODUCT(1/($C$2:$F$2),$C16:$F16)*100 -> 11.092515 | L16: =F16/F$2/SUMPRODUCT(1/($C$2:$F$2),$C16:$F16)*100 -> 10.157449 | M16: =SUM(I16:L16) -> 100
B17: NBF67.18.10-800 | C17: 18.23 | D17: 58.17 | E17: 12 | F17: 11.51 | H17: NBF67.18.10-800 | I17: =C17/C$2/SUMPRODUCT(1/($C$2:$F$2),$C17:$F17)*100 -> 16.533275 | J17: =D17/D$2/SUMPRODUCT(1/($C$2:$F$2),$C17:$F17)*100 -> 61.127268 | K17: =E17/E$2/SUMPRODUCT(1/($C$2:$F$2),$C17:$F17)*100 -> 12.224306 | L17: =F17/F$2/SUMPRODUCT(1/($C$2:$F$2),$C17:$F17)*100 -> 10.115151 | M17: =SUM(I17:L17) -> 100
... B19: NBF67.18.10-R15 | C19: 18.09 | D19: 59.12 | E19: 11.6 | F19: 11.35 | H19: NBF67.18.10-R15 | I19: =C19/C$2/SUMPRODUCT(1/($C$2:$F$2),$C19:$F19)*100 -> 16.353445 | J19: =D19/D$2/SUMPRODUCT(1/($C$2:$F$2),$C19:$F19)*100 -> 61.925397 | K19: =E19/E$2/SUMPRODUCT(1/($C$2:$F$2),$C19:$F19)*100 -> 11.778756 | L19: =F19/F$2/SUMPRODUCT(1/($C$2:$F$2),$C19:$F19)*100 -> 9.9424025 | M19: =SUM(I19:L19) -> 100
A22: Icenhower, Jonathan P., et al. "Experimentally determined dissolution kinetics of Na-rich borosilicate glass at far from equilibrium conditions: implications for transition state theory." Geochimica et Cosmochimica Acta 72.12 (2008): 2767-2788. | B22: wt% | C22: Al2O3 | D22: B2O3 | E22: CaO | F22: Cr2O3 | G22: Fe2O3 | H22: K2O | I22: La2O3 | J22: MgO | K22: Na2O | L22: P2O5 | M22: SO3 | N22: SiO2 | O22: TiO2 | P22: ZnO | Q22: ZrO2 | R22: sum
B23: LAWA44 | C23: 6.2 | D23: 8.9 | E23: 1.99 | F23: 0.02 | G23: 6.98 | H23: 0.5 | J23: 1.99 | K23: 20 | L23: 0.03 | M23: 0.1 | N23: 44.55 | O23: 1.99 | P23: 2.96 | Q23: 2.99 | R23: =SUM(C23:Q23) -> 99.2
B24: LAWABP1 | C24: 10 | D24: 9.25 | F24: 0.02 | G24: 2.5 | H24: 2.2 | I24: 2 | J24: 1 | K24: 20 | L24: 0.08 | M24: 0.1 | N24: 41.89 | O24: 2.49 | P24: 2.6 | Q24: 5.25 | R24: =SUM(C24:Q24) -> 99.38
B25: HLP-9 | C25: 6.84 | D25: 12 | E25: 0.01 | F25: 0.07 | G25: 5.38 | H25: 0.4 | J25: 1.47 | K25: 19.56 | L25: 0.05 | M25: 0.07 | N25: 47.98 | O25: 2.93 | P25: 1.47 | Q25: 1.47 | R25: =SUM(C25:Q25) -> 99.7
B26: mol% | C26: Al2O3 | D26: B2O3 | E26: CaO | F26: Cr2O3 | G26: Fe2O3 | H26: K2O | I26: La2O3 | J26: MgO | K26: Na2O | L26: P2O5 | M26: SO3 | N26: SiO2 | O26: TiO2 | P26: ZnO | Q26: ZrO2 | R26: sum
B27: LAWA44 | C27: {=C23/G$2/SUMPRODUCT($C23:$Q23,1/($G$2:$U$2))*100} -> 4.12574 | D27: =D23/H$2/SUMPRODUCT($C23:$Q23,1/($G$2:$U$2))*100 -> 8.6740929 | E27: =E23/I$2/SUMPRODUCT($C23:$Q23,1/($G$2:$U$2))*100 -> 2.4077848 | F27: =F23/J$2/SUMPRODUCT($C23:$Q23,1/($G$2:$U$2))*100 -> 0.0089282677 | G27: =G23/K$2/SUMPRODUCT($C23:$Q23,1/($G$2:$U$2))*100 -> 2.9657547 | H27: =H23/L$2/SUMPRODUCT($C23:$Q23,1/($G$2:$U$2))*100 -> 0.36015672 | I27: =I23/M$2/SUMPRODUCT($C23:$Q23,1/($G$2:$U$2))*100 -> 0 | J27: =J23/N$2/SUMPRODUCT($C23:$Q23,1/($G$2:$U$2))*100 -> 3.3500732 | K27: =K23/O$2/SUMPRODUCT($C23:$Q23,1/($G$2:$U$2))*100 -> 21.894488 | ... Q27: =Q23/U$2/SUMPRODUCT($C23:$Q23,1/($G$2:$U$2))*100 -> 1.6463884 | R27: =SUM(C27:Q27) -> 100
B28: LAWABP1 | C28: =C24/G$2/SUMPRODUCT($C24:$Q24,1/($G$2:$U$2))*100 -> 6.8657477 | D28: =D24/H$2/SUMPRODUCT($C24:$Q24,1/($G$2:$U$2))*100 -> 9.3015102 | E28: =E24/I$2/SUMPRODUCT($C24:$Q24,1/($G$2:$U$2))*100 -> 0 | F28: =F24/J$2/SUMPRODUCT($C24:$Q24,1/($G$2:$U$2))*100 -> 0.0092118079 | G28: =G24/K$2/SUMPRODUCT($C24:$Q24,1/($G$2:$U$2))*100 -> 1.095967 | H28: =H24/L$2/SUMPRODUCT($C24:$Q24,1/($G$2:$U$2))*100 -> 1.6350155 | I28: =I24/M$2/SUMPRODUCT($C24:$Q24,1/($G$2:$U$2))*100 -> 0.42971775 | J28: =J24/N$2/SUMPRODUCT($C24:$Q24,1/($G$2:$U$2))*100 -> 1.7369163 | ... Q28: =Q24/U$2/SUMPRODUCT($C24:$Q24,1/($G$2:$U$2))*100 -> 2.9826211 | R28: =SUM(C28:Q28) -> 100
B29: HLP-9 | C29: =C25/G$2/SUMPRODUCT($C25:$Q25,1/($G$2:$U$2))*100 -> 4.4825133 | D29: =D25/H$2/SUMPRODUCT($C25:$Q25,1/($G$2:$U$2))*100 -> 11.517829 | E29: =E25/I$2/SUMPRODUCT($C25:$Q25,1/($G$2:$U$2))*100 -> 0.011915709 | F29: =F25/J$2/SUMPRODUCT($C25:$Q25,1/($G$2:$U$2))*100 -> 0.030774468 | G29: =G25/K$2/SUMPRODUCT($C25:$Q25,1/($G$2:$U$2))*100 -> 2.2512172 | H29: =H25/L$2/SUMPRODUCT($C25:$Q25,1/($G$2:$U$2))*100 -> 0.28375062 | I29: =I25/M$2/SUMPRODUCT($C25:$Q25,1/($G$2:$U$2))*100 -> 0 | J29: =J25/N$2/SUMPRODUCT($C25:$Q25,1/($G$2:$U$2))*100 -> 2.4371029 | ... Q29: =Q25/U$2/SUMPRODUCT($C25:$Q25,1/($G$2:$U$2))*100 -> 0.79713845 | R29: =SUM(C29:Q29) -> 100
A31: Pierce, Eric M., et al. "Aluminoborosilicate waste glass dissolution under alkaline conditions at 40° C: implications for a chemical affinity-based rate equation." Environmental Chemistry 5.1 (2008): 73-85. | B31: wt% | C31: Al2O3 | D31: B2O3 | E31: CaO | F31: Cr2O3 | G31: Fe2O3 | H31: K2O | I31: La2O3 | J31: MgO | K31: Na2O | L31: P2O5 | M31: SO3 | N31: SiO2 | O31: TiO2 | P31: ZnO | Q31: ZrO2 | R31: Li2O | S31: sum
B32: LAWE-1A | C32: 6.1 | D32: 10 | E32: 2.03 | G32: 5.5 | H32: 3.73 | J32: 1.48 | K32: 19.05 | N32: 43.2 | O32: 1.4 | P32: 3.5 | Q32: 3 | S32: =SUM(C32:R32) -> 98.99
B33: LAWE-95A | C33: 6.1 | D33: 10 | E33: 6.94 | G33: 5.5 | H33: 0.241 | J33: 2.6 | K33: 7.75 | N33: 47.9 | O33: 1.4 | P33: 3.5 | Q33: 3 | R33: 4.18 | S33: =SUM(C33:R33) -> 99.111
B34: LAWE-290A | C34: 6.1 | D34: 10 | E34: 5.93 | G34: 5.5 | H34: 0.087 | J34: 1.49 | K34: 14.1 | N34: 44.8 | O34: 1.4 | P34: 3.5 | Q34: 3 | R34: 2.75 | S34: =SUM(C34:R34) -> 98.657
B35: mol% | C35: Al2O3 | D35: B2O3 | E35: CaO | F35: Cr2O3 | G35: Fe2O3 | H35: K2O | I35: La2O3 | J35: MgO | K35: Na2O | L35: P2O5 | M35: SO3 | N35: SiO2 | O35: TiO2 | P35: ZnO | Q35: ZrO2 | R35: Li2O | S35: sum
B36: LAWE-1A | C36: =C32/G$2/SUMPRODUCT($C32:$R32,1/($G$2:$V$2))*100 -> 4.0929581 | D36: =D32/H$2/SUMPRODUCT($C32:$R32,1/($G$2:$V$2))*100 -> 9.8272355 | E36: =E32/I$2/SUMPRODUCT($C32:$R32,1/($G$2:$V$2))*100 -> 2.4766118 | F36: =F32/J$2/SUMPRODUCT($C32:$R32,1/($G$2:$V$2))*100 -> 0 | G36: =G32/K$2/SUMPRODUCT($C32:$R32,1/($G$2:$V$2))*100 -> 2.35635 | H36: =H32/L$2/SUMPRODUCT($C32:$R32,1/($G$2:$V$2))*100 -> 2.7091163 | I36: =I32/M$2/SUMPRODUCT($C32:$R32,1/($G$2:$V$2))*100 -> 0 | J36: =J32/N$2/SUMPRODUCT($C32:$R32,1/($G$2:$V$2))*100 -> 2.5122348 | ... R36: =R32/V$2/SUMPRODUCT($C32:$R32,1/($G$2:$V$2))*100 -> 0 | S36: =SUM(C36:R36) -> 100
B37: LAWE-95A | C37: =C33/G$2/SUMPRODUCT($C33:$R33,1/($G$2:$V$2))*100 -> 3.7965701 | D37: =D33/H$2/SUMPRODUCT($C33:$R33,1/($G$2:$V$2))*100 -> 9.1156047 | E37: =E33/I$2/SUMPRODUCT($C33:$R33,1/($G$2:$V$2))*100 -> 7.8537213 | F37: =F33/J$2/SUMPRODUCT($C33:$R33,1/($G$2:$V$2))*100 -> 0 | G37: =G33/K$2/SUMPRODUCT($C33:$R33,1/($G$2:$V$2))*100 -> 2.1857169 | H37: =H33/L$2/SUMPRODUCT($C33:$R33,1/($G$2:$V$2))*100 -> 0.16236409 | I37: =I33/M$2/SUMPRODUCT($C33:$R33,1/($G$2:$V$2))*100 -> 0 | J37: =J33/N$2/SUMPRODUCT($C33:$R33,1/($G$2:$V$2))*100 -> 4.093794 | ... R37: =R33/V$2/SUMPRODUCT($C33:$R33,1/($G$2:$V$2))*100 -> 8.8779156 | S37: =SUM(C37:R37) -> 100
B38: LAWE-290A | C38: =C34/G$2/SUMPRODUCT($C34:$R34,1/($G$2:$V$2))*100 -> 3.9061028 | D38: =D34/H$2/SUMPRODUCT($C34:$R34,1/($G$2:$V$2))*100 -> 9.3785939 | E38: =E34/I$2/SUMPRODUCT($C34:$R34,1/($G$2:$V$2))*100 -> 6.9043525 | F38: =F34/J$2/SUMPRODUCT($C34:$R34,1/($G$2:$V$2))*100 -> 0 | G38: =G34/K$2/SUMPRODUCT($C34:$R34,1/($G$2:$V$2))*100 -> 2.2487758 | H38: =H34/L$2/SUMPRODUCT($C34:$R34,1/($G$2:$V$2))*100 -> 0.060303766 | I38: =I34/M$2/SUMPRODUCT($C34:$R34,1/($G$2:$V$2))*100 -> 0 | J38: =J34/N$2/SUMPRODUCT($C34:$R34,1/($G$2:$V$2))*100 -> 2.4137437 | ... R38: =R34/V$2/SUMPRODUCT($C34:$R34,1/($G$2:$V$2))*100 -> 6.0092417 | S38: =SUM(C38:R38) -> 100
C40: K=SiO2/B2O3 | D40: R=Na2O/B2O3 | K40: Mol%
A41: Yun, Y. H., and P. J. Bray. "Nuclear magnetic resonance studies of the glasses in the system Na2O-B2O3-SiO2." Journal of Non-Crystalline Solids 27.3 (1978): 363-380. | B41: Sample No. | C41: K | D41: R | E41: N4 | G41: SiO2 | H41: Na2O | I41: B2O3 | K41: SiO2 | L41: Na2O | M41: B2O3 | N41: sum
B42: a) | C42: 0 | D42: 0.11 | E42: =F42*100 -> 11.6 | F42: 0.116 | G42: =C42 -> 0 | H42: =D42 -> 0.11 | I42: 1 | K42: =G42/SUM($G42:$I42)*100 -> 0 | L42: =H42/SUM($G42:$I42)*100 -> 9.9099099 | M42: =I42/SUM($G42:$I42)*100 -> 90.09009 | N42: =SUM(K42:M42) -> 100
B43: a) | C43: 0 | D43: 0.177 | E43: =F43*100 -> 16 | F43: 0.16 | G43: =C43 -> 0 | H43: =D43 -> 0.177 | I43: 1 | K43: =G43/SUM($G43:$I43)*100 -> 0 | L43: =H43/SUM($G43:$I43)*100 -> 15.038233 | M43: =I43/SUM($G43:$I43)*100 -> 84.961767 | N43: =SUM(K43:M43) -> 100
B44: a) | C44: 0 | D44: 0.205 | E44: =F44*100 -> 22.5 | F44: 0.225 | G44: =C44 -> 0 | H44: =D44 -> 0.205 | I44: 1 | K44: =G44/SUM($G44:$I44)*100 -> 0 | L44: =H44/SUM($G44:$I44)*100 -> 17.012448 | M44: =I44/SUM($G44:$I44)*100 -> 82.987552 | N44: =SUM(K44:M44) -> 100
B45: a) | C45: 0 | D45: 0.25 | E45: =F45*100 -> 28 | F45: 0.28 | G45: =C45 -> 0 | H45: =D45 -> 0.25 | I45: 1 | K45: =G45/SUM($G45:$I45)*100 -> 0 | L45: =H45/SUM($G45:$I45)*100 -> 20 | M45: =I45/SUM($G45:$I45)*100 -> 80 | N45: =SUM(K45:M45) -> 100
B46: a) | C46: 0 | D46: 0.282 | E46: =F46*100 -> 27.5 | F46: 0.275 | G46: =C46 -> 0 | H46: =D46 -> 0.282 | I46: 1 | K46: =G46/SUM($G46:$I46)*100 -> 0 | L46: =H46/SUM($G46:$I46)*100 -> 21.99688 | M46: =I46/SUM($G46:$I46)*100 -> 78.00312 | N46: =SUM(K46:M46) -> 100
...

Sheet JDV (full data)(same coef)
A1: # | B1: new # | C1: Glass ID | D1: Outlier | E1: Alk+AE | F1: Si/(Si+B+P+Te) | G1: Al2O3 | H1: B2O3 | I1: CaO | J1: Cr2O3 | K1: Fe2O3 | L1: K2O | M1: Li2O | N1: MgO | O1: Na2O | P1: P2O5 | Q1: SiO2 | R1: SO3 | S1: TiO2 | T1: ZnO | U1: ZrO2 | V1: BaO | W1: Bi2O3 | X1: Cs2O | Y1: HfO2 | Z1: La2O3 | AA1: PbO | AB1: SrO | AC1: TeO2 | AD1: Rb2O | AE1: UO3 | AF1: Y2O3 | AG1: N4 (%) | AH1: Method | AI1: Cooling rate | AJ1: Annealing | AK1: Sample form | AL1: Pressure | AM1: Note | AN1: sum | AO1: Alk=[Cs,K,Na,Li]2O | AP1: Al2O3 | AQ1: B2O3 | AR1: SiO2 | AS1: N4 | AT1: du-stebbins | AU1: K'=[SiO2]/([B2O3]+[Al2O3]) | AV1: R'=([Alk])/([B2O3]+[Al2O3]) | AW1: R'max=0.5+K'/16 | AX1: R'D1=0.5+K'/4 | AY1: N'4 | AZ1: Adj N'4 | BA1: abs Res | BB1: Modified | BC1: K''=([SiO2]+e[TeO2])/(a[B2O3]+b[Al2O3]+c[P2O5]+...) | BD1: R''=([Na2O]+x[Li2O]+...)/(a[B2O3]+b[Al2O3]+...) | BE1: R''max=m+K''*n | BF1: R''D1=o+K''*p | BG1: N''4 | BH1: Adj N''4 | BI1: squares | BJ1: var | BL1: Modified | BN1: valence
A2: 243 | B2: 502 | C2: ='EWG-CCP-127 (1)'!B58 -> 3 | D2: 1 | E2: =I2+L2+M2+N2+O2+V2+X2+AB2+AD2 -> 18.032787 | F2: =Q2/(H2+P2+Q2+AC2) -> 0.33333333 | G2: 0 | H2: ='EWG-CCP-127 (1)'!M58 -> 54.644809 | I2: 0 | J2: 0 | K2: 0 | L2: 0 | M2: 0 | N2: 0 | O2: ='EWG-CCP-127 (1)'!L58 -> 18.032787 | P2: 0 | Q2: ='EWG-CCP-127 (1)'!K58 -> 27.322404 | R2: 0 | S2: 0 | T2: 0 | U2: 0 | V2: 0 | W2: 0 | X2: 0 | Y2: 0 | Z2: 0 | AA2: 0 | AB2: 0 | AC2: 0 | AD2: 0 | AE2: 0 | AF2: 0 | AG2: ='EWG-CCP-127 (1)'!E58 -> 33 | AH2: NMR | AI2: Air quench | AN2: =SUM(G2:AF2) -> 100 | AO2: =(L2+M2+O2+X2)/100 -> 0.18032787 | AP2: =G2/100 -> 0 | AQ2: =H2/100 -> 0.54644809 | AR2: =Q2/100 -> 0.27322404 | AS2: =AG2/100 -> 0.33 | AU2: =AR2/(AQ2+AP2) -> 0.5 | AV2: =AO2/(AP2+AQ2) -> 0.33 | AW2: =0.5+AU2/16 -> 0.53125 | AX2: =0.5+AU2/4 -> 0.625 | AY2: =IF(AV2<=AW2,AV2,IF(AV2<=AX2,AW2,AW2-(AV2-AX2)*(8+AU2)/(12*(2+AU2)))) -> 0.33 | AZ2: =IF(AY2<1,AY2,1) -> 0.33 | BA2: =ABS(AZ2-AS2) -> 5.5511151e-17 | BC2: =(Q2)/($BM$3*H2+$BM$4*G2+$BM$5*P2+$BM$6*K2+$BM$7*S2+$BM$8*U2+$BM$9*Y2) -> 0.5 | BD2: =(O2+$BM$11*M2+$BM$12*L2+$BM$13*X2+$BM$14*AD2+$BM$15*I2+$BM$16*N2+$BM$17*AB2+$BM$18*V2+$BM$19*T2+$BM$20*AA2+$BM$21*Z2+$BM$22*AF2+$BM$23*W2)/($BM$3*$H2+$BM$4*$G2+$BM$5*$P2+$BM$6*$K2+$BM$7*$S2+$BM$8*$U2+$BM$9*$Y2) -> 0.33 | BE2: =$BM$25+BC2*$BM$26 -> 0.59927954 | BF2: =$BM$27+BC2*$BM$28 -> 0.34712845 | BG2: =IF(BD2<=BE2,BD2,IF(BD2<=BF2,BE2,BE2-(BD2-BF2)*(8+BC2)/(12*(2+BC2)))) -> 0.33 | BH2: =IF(BG2<1,IF(BG2>0,BG2,0),1) -> 0.33 | BI2: =(BH2-AS2)^2 -> 0 | BJ2: =(AS2-AVERAGE($AS$2:$AS$647))^2 -> 0.0059094513 | BL2: K'' coef
A3: 261 | B3: 152 | C3: ='EWG-CCP-127 (1)'!B76 -> 21 | D3: 1 | E3: =I3+L3+M3+N3+O3+V3+X3+AB3+AD3 -> 6.25 | F3: =Q3/(H3+P3+Q3+AC3) -> 0.66666667 | G3: 0 | H3: ='EWG-CCP-127 (1)'!M76 -> 31.25 | I3: 0 | J3: 0 | K3: 0 | L3: 0 | M3: 0 | N3: 0 | O3: ='EWG-CCP-127 (1)'!L76 -> 6.25 | P3: 0 | Q3: ='EWG-CCP-127 (1)'!K76 -> 62.5 | R3: 0 | S3: 0 | T3: 0 | U3: 0 | V3: 0 | W3: 0 | X3: 0 | Y3: 0 | Z3: 0 | AA3: 0 | AB3: 0 | AC3: 0 | AD3: 0 | AE3: 0 | AF3: 0 | AG3: ='EWG-CCP-127 (1)'!E76 -> 20 | AH3: NMR | AI3: Air quench | AN3: =SUM(G3:AF3) -> 100 | AO3: =(L3+M3+O3+X3)/100 -> 0.0625 | AP3: =G3/100 -> 0 | AQ3: =H3/100 -> 0.3125 | AR3: =Q3/100 -> 0.625 | AS3: =AG3/100 -> 0.2 | AU3: =AR3/(AQ3+AP3) -> 2 | AV3: =AO3/(AP3+AQ3) -> 0.2 | AW3: =0.5+AU3/16 -> 0.625 | AX3: =0.5+AU3/4 -> 1 | AY3: =IF(AV3<=AW3,AV3,IF(AV3<=AX3,AW3,AW3-(AV3-AX3)*(8+AU3)/(12*(2+AU3)))) -> 0.2 | AZ3: =IF(AY3<1,AY3,1) -> 0.2 | BA3: =ABS(AZ3-AS3) -> 0 | BC3: =(Q3)/($BM$3*H3+$BM$4*G3+$BM$5*P3+$BM$6*K3+$BM$7*S3+$BM$8*U3+$BM$9*Y3) -> 2 | BD3: =(O3+$BM$11*M3+$BM$12*L3+$BM$13*X3+$BM$14*AD3+$BM$15*I3+$BM$16*N3+$BM$17*AB3+$BM$18*V3+$BM$19*T3+$BM$20*AA3+$BM$21*Z3+$BM$22*AF3+$BM$23*W3)/($BM$3*$H3+$BM$4*$G3+$BM$5*$P3+$BM$6*$K3+$BM$7*$S3+$BM$8*$U3+$BM$9*$Y3) -> 0.2 | BE3: =$BM$25+BC3*$BM$26 -> 0.62764378 | BF3: =$BM$27+BC3*$BM$28 -> 1.1005923 | BG3: =IF(BD3<=BE3,BD3,IF(BD3<=BF3,BE3,BE3-(BD3-BF3)*(8+BC3)/(12*(2+BC3)))) -> 0.2 | BH3: =IF(BG3<1,IF(BG3>0,BG3,0),1) -> 0.2 | BI3: =(BH3-AS3)^2 -> 0 | BJ3: =(AS3-AVERAGE($AS$2:$AS$647))^2 -> 0.04279642 | BL3: B2O3 | BM3: 1
A4: 315 | B4: 202 | D4: 1 | E4: =I4+L4+M4+N4+O4+V4+X4+AB4+AD4 -> 11.111111 | F4: =Q4/(H4+P4+Q4+AC4) -> 0.75 | G4: 0 | H4: ='EWG-CCP-127 (1)'!M133 -> 22.222222 | I4: 0 | J4: 0 | K4: 0 | L4: 0 | M4: 0 | N4: 0 | O4: ='EWG-CCP-127 (1)'!L133 -> 11.111111 | P4: 0 | Q4: ='EWG-CCP-127 (1)'!K133 -> 66.666667 | R4: 0 | S4: 0 | T4: 0 | U4: 0 | V4: 0 | W4: 0 | X4: 0 | Y4: 0 | Z4: 0 | AA4: 0 | AB4: 0 | AC4: 0 | AD4: 0 | AE4: 0 | AF4: 0 | AG4: ='EWG-CCP-127 (1)'!E133 -> 50 | AH4: NMR | AI4: Water quench | AN4: =SUM(G4:AF4) -> 100 | AO4: =(L4+M4+O4+X4)/100 -> 0.11111111 | AP4: =G4/100 -> 0 | AQ4: =H4/100 -> 0.22222222 | AR4: =Q4/100 -> 0.66666667 | AS4: =AG4/100 -> 0.5 | AU4: =AR4/(AQ4+AP4) -> 3 | AV4: =AO4/(AP4+AQ4) -> 0.5 | AW4: =0.5+AU4/16 -> 0.6875 | AX4: =0.5+AU4/4 -> 1.25 | AY4: =IF(AV4<=AW4,AV4,IF(AV4<=AX4,AW4,AW4-(AV4-AX4)*(8+AU4)/(12*(2+AU4)))) -> 0.5 | AZ4: =IF(AY4<1,AY4,1) -> 0.5 | BA4: =ABS(AZ4-AS4) -> 0 | BC4: =(Q4)/($BM$3*H4+$BM$4*G4+$BM$5*P4+$BM$6*K4+$BM$7*S4+$BM$8*U4+$BM$9*Y4) -> 3 | BD4: =(O4+$BM$11*M4+$BM$12*L4+$BM$13*X4+$BM$14*AD4+$BM$15*I4+$BM$16*N4+$BM$17*AB4+$BM$18*V4+$BM$19*T4+$BM$20*AA4+$BM$21*Z4+$BM$22*AF4+$BM$23*W4)/($BM$3*$H4+$BM$4*$G4+$BM$5*$P4+$BM$6*$K4+$BM$7*$S4+$BM$8*$U4+$BM$9*$Y4) -> 0.5 | BE4: =$BM$25+BC4*$BM$26 -> 0.64655327 | BF4: =$BM$27+BC4*$BM$28 -> 1.6029016 | BG4: =IF(BD4<=BE4,BD4,IF(BD4<=BF4,BE4,BE4-(BD4-BF4)*(8+BC4)/(12*(2+BC4)))) -> 0.5 | BH4: =IF(BG4<1,IF(BG4>0,BG4,0),1) -> 0.5 | BI4: =(BH4-AS4)^2 -> 0 | BJ4: =(AS4-AVERAGE($AS$2:$AS$647))^2 -> 0.0086726464 | BL4: Al2O3 | BM4: 4
A5: 354 | B5: 376 | C5: 4 | D5: 1 | E5: =I5+L5+M5+N5+O5+V5+X5+AB5+AD5 -> 66.666667 | F5: =Q5/(H5+P5+Q5+AC5) -> 0.5 | G5: 0 | H5: ='EWG-CCP-127 (1)'!M167 -> 16.666667 | I5: 0 | J5: 0 | K5: 0 | L5: 0 | M5: 0 | N5: 0 | O5: ='EWG-CCP-127 (1)'!L167 -> 66.666667 | P5: 0 | Q5: ='EWG-CCP-127 (1)'!K167 -> 16.666667 | R5: 0 | S5: 0 | T5: 0 | U5: 0 | V5: 0 | W5: 0 | X5: 0 | Y5: 0 | Z5: 0 | AA5: 0 | AB5: 0 | AC5: 0 | AD5: 0 | AE5: 0 | AF5: 0 | AG5: ='EWG-CCP-127 (1)'!E167 -> 0 | AH5: NMR | AI5: Air quench | AN5: =SUM(G5:AF5) -> 100 | AO5: =(L5+M5+O5+X5)/100 -> 0.66666667 | AP5: =G5/100 -> 0 | AQ5: =H5/100 -> 0.16666667 | AR5: =Q5/100 -> 0.16666667 | AS5: =AG5/100 -> 0 | AU5: =AR5/(AQ5+AP5) -> 1 | AV5: =AO5/(AP5+AQ5) -> 4 | AW5: =0.5+AU5/16 -> 0.5625 | AX5: =0.5+AU5/4 -> 0.75 | AY5: =IF(AV5<=AW5,AV5,IF(AV5<=AX5,AW5,AW5-(AV5-AX5)*(8+AU5)/(12*(2+AU5)))) -> -0.25 | AZ5: =IF(AY5<1,AY5,1) -> -0.25 | BA5: =ABS(AZ5-AS5) -> 0.25 | BC5: =(Q5)/($BM$3*H5+$BM$4*G5+$BM$5*P5+$BM$6*K5+$BM$7*S5+$BM$8*U5+$BM$9*Y5) -> 1 | BD5: =(O5+$BM$11*M5+$BM$12*L5+$BM$13*X5+$BM$14*AD5+$BM$15*I5+$BM$16*N5+$BM$17*AB5+$BM$18*V5+$BM$19*T5+$BM$20*AA5+$BM$21*Z5+$BM$22*AF5+$BM$23*W5)/($BM$3*$H5+$BM$4*$G5+$BM$5*$P5+$BM$6*$K5+$BM$7*$S5+$BM$8*$U5+$BM$9*$Y5) -> 4 | BE5: =$BM$25+BC5*$BM$26 -> 0.60873429 | BF5: =$BM$27+BC5*$BM$28 -> 0.59828308 | BG5: =IF(BD5<=BE5,BD5,IF(BD5<=BF5,BE5,BE5-(BD5-BF5)*(8+BC5)/(12*(2+BC5)))) -> -0.24169494 | BH5: =IF(BG5<1,IF(BG5>0,BG5,0),1) -> 0 | BI5: =(BH5-AS5)^2 -> 0 | BJ5: =(AS5-AVERAGE($AS$2:$AS$647))^2 -> 0.1655456 | BL5: P2O5 | BM5: 0
A6: 360 | B6: 380 | C6: 10 | D6: 1 | E6: =I6+L6+M6+N6+O6+V6+X6+AB6+AD6 -> 62.5 | F6: =Q6/(H6+P6+Q6+AC6) -> 0.66666667 | G6: 0 | H6: ='EWG-CCP-127 (1)'!M173 -> 12.5 | I6: 0 | J6: 0 | K6: 0 | L6: 0 | M6: 0 | N6: 0 | O6: ='EWG-CCP-127 (1)'!L173 -> 62.5 | P6: 0 | Q6: ='EWG-CCP-127 (1)'!K173 -> 25 | R6: 0 | S6: 0 | T6: 0 | U6: 0 | V6: 0 | W6: 0 | X6: 0 | Y6: 0 | Z6: 0 | AA6: 0 | AB6: 0 | AC6: 0 | AD6: 0 | AE6: 0 | AF6: 0 | AG6: ='EWG-CCP-127 (1)'!E173 -> 0 | AH6: NMR | AI6: Air quench | AN6: =SUM(G6:AF6) -> 100 | AO6: =(L6+M6+O6+X6)/100 -> 0.625 | AP6: =G6/100 -> 0 | AQ6: =H6/100 -> 0.125 | AR6: =Q6/100 -> 0.25 | AS6: =AG6/100 -> 0 | AU6: =AR6/(AQ6+AP6) -> 2 | AV6: =AO6/(AP6+AQ6) -> 5 | AW6: =0.5+AU6/16 -> 0.625 | AX6: =0.5+AU6/4 -> 1 | AY6: =IF(AV6<=AW6,AV6,IF(AV6<=AX6,AW6,AW6-(AV6-AX6)*(8+AU6)/(12*(2+AU6)))) -> -0.20833333 | AZ6: =IF(AY6<1,AY6,1) -> -0.20833333 | BA6: =ABS(AZ6-AS6) -> 0.20833333 | BC6: =(Q6)/($BM$3*H6+$BM$4*G6+$BM$5*P6+$BM$6*K6+$BM$7*S6+$BM$8*U6+$BM$9*Y6) -> 2 | BD6: =(O6+$BM$11*M6+$BM$12*L6+$BM$13*X6+$BM$14*AD6+$BM$15*I6+$BM$16*N6+$BM$17*AB6+$BM$18*V6+$BM$19*T6+$BM$20*AA6+$BM$21*Z6+$BM$22*AF6+$BM$23*W6)/($BM$3*$H6+$BM$4*$G6+$BM$5*$P6+$BM$6*$K6+$BM$7*$S6+$BM$8*$U6+$BM$9*$Y6) -> 5 | BE6: =$BM$25+BC6*$BM$26 -> 0.62764378 | BF6: =$BM$27+BC6*$BM$28 -> 1.1005923 | BG6: =IF(BD6<=BE6,BD6,IF(BD6<=BF6,BE6,BE6-(BD6-BF6)*(8+BC6)/(12*(2+BC6)))) -> -0.18473282 | BH6: =IF(BG6<1,IF(BG6>0,BG6,0),1) -> 0 | BI6: =(BH6-AS6)^2 -> 0 | BJ6: =(AS6-AVERAGE($AS$2:$AS$647))^2 -> 0.1655456 | BL6: Fe2O3 | BM6: 0
A7: 367 | B7: 383 | C7: 17 | D7: 1 | E7: =I7+L7+M7+N7+O7+V7+X7+AB7+AD7 -> 60 | F7: =Q7/(H7+P7+Q7+AC7) -> 0.75 | G7: 0 | H7: ='EWG-CCP-127 (1)'!M180 -> 10 | I7: 0 | J7: 0 | K7: 0 | L7: 0 | M7: 0 | N7: 0 | O7: ='EWG-CCP-127 (1)'!L180 -> 60 | P7: 0 | Q7: ='EWG-CCP-127 (1)'!K180 -> 30 | R7: 0 | S7: 0 | T7: 0 | U7: 0 | V7: 0 | W7: 0 | X7: 0 | Y7: 0 | Z7: 0 | AA7: 0 | AB7: 0 | AC7: 0 | AD7: 0 | AE7: 0 | AF7: 0 | AG7: ='EWG-CCP-127 (1)'!E180 -> 0 | AH7: NMR | AI7: Air quench | AN7: =SUM(G7:AF7) -> 100 | AO7: =(L7+M7+O7+X7)/100 -> 0.6 | AP7: =G7/100 -> 0 | AQ7: =H7/100 -> 0.1 | AR7: =Q7/100 -> 0.3 | AS7: =AG7/100 -> 0 | AU7: =AR7/(AQ7+AP7) -> 3 | AV7: =AO7/(AP7+AQ7) -> 6 | AW7: =0.5+AU7/16 -> 0.6875 | AX7: =0.5+AU7/4 -> 1.25 | AY7: =IF(AV7<=AW7,AV7,IF(AV7<=AX7,AW7,AW7-(AV7-AX7)*(8+AU7)/(12*(2+AU7)))) -> -0.18333333 | AZ7: =IF(AY7<1,AY7,1) -> -0.18333333 | BA7: =ABS(AZ7-AS7) -> 0.18333333 | BC7: =(Q7)/($BM$3*H7+$BM$4*G7+$BM$5*P7+$BM$6*K7+$BM$7*S7+$BM$8*U7+$BM$9*Y7) -> 3 | BD7: =(O7+$BM$11*M7+$BM$12*L7+$BM$13*X7+$BM$14*AD7+$BM$15*I7+$BM$16*N7+$BM$17*AB7+$BM$18*V7+$BM$19*T7+$BM$20*AA7+$BM$21*Z7+$BM$22*AF7+$BM$23*W7)/($BM$3*$H7+$BM$4*$G7+$BM$5*$P7+$BM$6*$K7+$BM$7*$S7+$BM$8*$U7+$BM$9*$Y7) -> 6 | BE7: =$BM$25+BC7*$BM$26 -> 0.64655327 | BF7: =$BM$27+BC7*$BM$28 -> 1.6029016 | BG7: =IF(BD7<=BE7,BD7,IF(BD7<=BF7,BE7,BE7-(BD7-BF7)*(8+BC7)/(12*(2+BC7)))) -> -0.15958144 | BH7: =IF(BG7<1,IF(BG7>0,BG7,0),1) -> 0 | BI7: =(BH7-AS7)^2 -> 0 | BJ7: =(AS7-AVERAGE($AS$2:$AS$647))^2 -> 0.1655456 | BL7: TiO2 | BM7: 0
A8: 368 | B8: 384 | C8: 18 | D8: 1 | E8: =I8+L8+M8+N8+O8+V8+X8+AB8+AD8 -> 63.636364 | F8: =Q8/(H8+P8+Q8+AC8) -> 0.75 | G8: 0 | H8: ='EWG-CCP-127 (1)'!M181 -> 9.0909091 | I8: 0 | J8: 0 | K8: 0 | L8: 0 | M8: 0 | N8: 0 | O8: ='EWG-CCP-127 (1)'!L181 -> 63.636364 | P8: 0 | Q8: ='EWG-CCP-127 (1)'!K181 -> 27.272727 | R8: 0 | S8: 0 | T8: 0 | U8: 0 | V8: 0 | W8: 0 | X8: 0 | Y8: 0 | Z8: 0 | AA8: 0 | AB8: 0 | AC8: 0 | AD8: 0 | AE8: 0 | AF8: 0 | AG8: ='EWG-CCP-127 (1)'!E181 -> 0 | AH8: NMR | AI8: Air quench | AN8: =SUM(G8:AF8) -> 100 | AO8: =(L8+M8+O8+X8)/100 -> 0.63636364 | AP8: =G8/100 -> 0 | AQ8: =H8/100 -> 0.090909091 | AR8: =Q8/100 -> 0.27272727 | AS8: =AG8/100 -> 0 | AU8: =AR8/(AQ8+AP8) -> 3 | AV8: =AO8/(AP8+AQ8) -> 7 | AW8: =0.5+AU8/16 -> 0.6875 | AX8: =0.5+AU8/4 -> 1.25 | AY8: =IF(AV8<=AW8,AV8,IF(AV8<=AX8,AW8,AW8-(AV8-AX8)*(8+AU8)/(12*(2+AU8)))) -> -0.36666667 | AZ8: =IF(AY8<1,AY8,1) -> -0.36666667 | BA8: =ABS(AZ8-AS8) -> 0.36666667 | BC8: =(Q8)/($BM$3*H8+$BM$4*G8+$BM$5*P8+$BM$6*K8+$BM$7*S8+$BM$8*U8+$BM$9*Y8) -> 3 | BD8: =(O8+$BM$11*M8+$BM$12*L8+$BM$13*X8+$BM$14*AD8+$BM$15*I8+$BM$16*N8+$BM$17*AB8+$BM$18*V8+$BM$19*T8+$BM$20*AA8+$BM$21*Z8+$BM$22*AF8+$BM$23*W8)/($BM$3*$H8+$BM$4*$G8+$BM$5*$P8+$BM$6*$K8+$BM$7*$S8+$BM$8*$U8+$BM$9*$Y8) -> 7 | BE8: =$BM$25+BC8*$BM$26 -> 0.64655327 | BF8: =$BM$27+BC8*$BM$28 -> 1.6029016 | BG8: =IF(BD8<=BE8,BD8,IF(BD8<=BF8,BE8,BE8-(BD8-BF8)*(8+BC8)/(12*(2+BC8)))) -> -0.34291477 | BH8: =IF(BG8<1,IF(BG8>0,BG8,0),1) -> 0 | BI8: =(BH8-AS8)^2 -> 0 | BJ8: =(AS8-AVERAGE($AS$2:$AS$647))^2 -> 0.1655456 | BL8: ZrO2 | BM8: 3
